Workbook

Sheet Company OKRs
A1: Company OKRs
A2: MyCityApp and MyLagosApp · Q4 2026 (Oct–Dec) · Foundation draft for review
A3: Each key result states what must be true at its finish date. [TBC] marks a provisional target, locked by 7 November from the verified baseline (CO-KR1.1). Accountable owners report in the columns to the right; a KR with a Scored from entry takes its figures from that function KR.
K4: Latest — updated at each monthly report | N4: Score by month
A5: KR ID | B5: Key result | C5: Type | D5: Accountable | E5: Contributing function KRs | F5: Baseline / target status | G5: Start | H5: Finish | I5: Initiatives (date) | J5: Scored from | K5: Status | L5: Actual | M5: Update | N5: October | O5: November | P5: December · Q4 final
A6: CO-O1 Build one trusted view of company performance. | N6: =IFERROR(ROUND(AVERAGE(N7:N8),2),"") | O6: =IFERROR(ROUND(AVERAGE(O7:O8),2),"") | P6: =IFERROR(ROUND(AVERAGE(P7:P8),2),"")
A7: CO-KR1.1 | B7: One verified opening baseline is signed off by the CEO and the finance owner by 31 October. It covers, per app: verified downloads (Play Console and App Store Connect, not store bands), monthly active users, completed transactions by type, paid-ticket value, and revenue by stream for January–September. | C7: Diagnostic gate — retires on sign-off | D7: CEO with interim finance owner | E7: TBO-KR2.3 | F7: Figures conflict today: store bands show 100K+ and 10K+ downloads, the CEO cited about 17K, and the dashboard is disputed. | G7: 46296 | H7: 46326 | I7: • Pull downloads from Play Console and App Store Connect for all three apps — 10 Oct • Pull provider and settlement records for bills, tickets and wallet — 17 Oct • Reconcile revenue by stream to bank and invoice records — finance owner, 24 Oct • Lock all [TBC] targets from the signed baseline — CEO, 7 Nov
A8: CO-KR1.2 | B8: A product analytics tool is contracted by 15 October and records install, first qualifying action, ticket purchase, bill and LASG payment, business contact and booking request in both apps by 15 November. The November report reconciles to provider and settlement records within 2%. | C8: Visibility gate — retires when two consecutive monthly reports reconcile | D8: Technology & Back-office Ops | E8: TBO-KR2.3 | F8: No analytics tool in use (no Mixpanel, Amplitude or equivalent). Interim: backend and provider records. | G8: 46296 | H8: 46356 | I8: See TBO-KR2.3 | J8: TBO-KR2.3 | K8: =IF('Technology & Back-office Ops'!I13="","",'Technology & Back-office Ops'!I13) | L8: =IF('Technology & Back-office Ops'!J13="","",'Technology & Back-office Ops'!J13) | M8: =IF('Technology & Back-office Ops'!K13="","",'Technology & Back-office Ops'!K13) -> Pending Review/tool identification | N8: =IF('Technology & Back-office Ops'!L13="","",'Technology & Back-office Ops'!L13) | O8: =IF('Technology & Back-office Ops'!M13="","",'Technology & Back-office Ops'!M13) | P8: =IF('Technology & Back-office Ops'!N13="","",'Technology & Back-office Ops'!N13)
A9: CO-O2 Make every customer journey work reliably. | N9: =IFERROR(ROUND(AVERAGE(N10:N13),2),"") | O9: =IFERROR(ROUND(AVERAGE(O10:O13),2),"") | P9: =IFERROR(ROUND(AVERAGE(P10:P13),2),"")
A10: CO-KR2.1 | B10: At least 95% of valid bill-payment and LASG-payment attempts complete successfully in December, in each app. | C10: Outcome | D10: Technology & Back-office Ops | E10: TBO-KR1.1; TBO-KR2.2 | F10: Baseline [TBC] from CO-KR1.1. Bill payments are reported as unstable. | G10: 46296 | H10: 46387 | I10: See TBO-KR1.1 and TBO-KR2.2
A11: CO-KR2.2 | B11: At least 97% of valid ticket-purchase attempts in December result in a valid ticket, with zero duplicate charges and zero oversold events. | C11: Outcome | D11: Technology & Back-office Ops | E11: TBO-KR1.2; TBO-KR2.2 | F11: Baseline [TBC] | G11: 46296 | H11: 46387 | I11: See TBO-KR1.2 | J11: TBO-KR1.2 | K11: =IF('Technology & Back-office Ops'!I8="","",'Technology & Back-office Ops'!I8) -> On track | L11: =IF('Technology & Back-office Ops'!J8="","",'Technology & Back-office Ops'!J8) | M11: =IF('Technology & Back-office Ops'!K8="","",'Technology & Back-office Ops'!K8) -> Blue salt upgrade upgrade done. Pending go-live. Temporary freeze on MTNN. - TBD. | N11: =IF('Technology & Back-office Ops'!L8="","",'Technology & Back-office Ops'!L8) | O11: =IF('Technology & Back-office Ops'!M8="","",'Technology & Back-office Ops'!M8) | P11: =IF('Technology & Back-office Ops'!N8="","",'Technology & Back-office Ops'!N8)
A12: CO-KR2.3 | B12: A staffed customer-support service with a named owner, published channels and a case log is live by 15 November. It resolves at least 85% of December cases within 48 hours. | C12: Enabling → Outcome | D12: Technology & Back-office Ops | E12: TBO-KR1.3; PC-KR2.2 | F12: No support service exists | G12: 46296 | H12: 46387 | I12: See TBO-KR1.3 and PC-KR2.2 | J12: TBO-KR1.3 | K12: =IF('Technology & Back-office Ops'!I9="","",'Technology & Back-office Ops'!I9) -> On track | L12: =IF('Technology & Back-office Ops'!J9="","",'Technology & Back-office Ops'!J9) | M12: =IF('Technology & Back-office Ops'!K9="","",'Technology & Back-office Ops'!K9) -> Ifeoma's TA hiring - Cynthia (Interviews in progress) Recommend Support Ticket Desk - Bode. Explore the ERP solution development/implementation in progress. | N12: =IF('Technology & Back-office Ops'!L9="","",'Technology & Back-office Ops'!L9) | O12: =IF('Technology & Back-office Ops'!M9="","",'Technology & Back-office Ops'!M9) | P12: =IF('Technology & Back-office Ops'!N9="","",'Technology & Back-office Ops'!N9)
A13: CO-KR2.4 | B13: All Q4 P0 capabilities are live in MyLagosApp and MyCityApp by 30 November: restaurant booking, in-restaurant payment, hotel and shortlet booking, the UI/UX redesign of both apps, and the BlueSalt API v2 upgrade. The P1 capabilities (merchant payment for other merchants, including payment in-store, and FAAN airport taxi booking) are live by 30 November, or the CEO re-dates them by 15 November. | C13: Output — enabling; retires on release | D13: Technology & Back-office Ops | E13: TBO-KR2.1; PG-KR1.3 | F13: CEO priorities, 30 Sep; restaurant scope confirmed 7 Oct. On 4 Oct merchant payment and FAAN taxi were at ideation. | G13: 46296 | H13: 46356 | I13: • CEO-approved roadmap sequencing every item with an MTNN delivery month and an acceptance owner, including automatic event expiry, bulk listing upload, the merchant collection web app and in-app business wallet visibility; Flex wallet paused, wallet stays on Sterling Embedly — CEO, 15 Oct • See TBO-KR2.1
A14: CO-O3 Make MyCityApp the go-to app for December in Nigeria's major cities. | N14: =IFERROR(ROUND(AVERAGE(N15:N17),2),"") | O14: =IFERROR(ROUND(AVERAGE(O15:O17),2),"") | P14: =IFERROR(ROUND(AVERAGE(P15:P17),2),"")
A15: CO-KR3.1 | B15: ₦250 million in paid-ticket value is processed in Q4, net of cancellations and refunds, across at least 200 ticketed events. At least 25 December events sell tickets through the apps on exclusive terms: an allocation, price or access benefit not offered on other ticketing platforms. | C15: Outcome | D15: Partnership & Growth | E15: TBO-KR3.2; BM-KR2.1; BM-KR2.3; PG-KR1.1; PG-KR2.3 | F15: 50% of the ₦500m ticket-value reference, as the December festive push (CEO decision 13); 200 events is 10% of the 2,000-event reference. Baseline [TBC]. | G15: 46296 | H15: 46387 | I15: See PG-KR1.1, PG-KR2.3 and BM-KR2.1
A16: CO-KR3.2 | B16: Assisted hotel and shortlet booking and restaurant booking are live in MyLagosApp and MyCityApp by 30 November. At least 100 December stays [TBC] and [TBC] restaurant bookings are confirmed by the partner and fulfilled. Technology & Back-office Ops owns the booking journeys; Partnership & Growth owns inventory and partner confirmation. | C16: Outcome — co-owned | D16: Technology & Back-office Ops (journey) / Partnership & Growth (inventory) | E16: TBO-KR2.1; TBO-KR3.2; PG-KR1.2; PG-KR1.3 | F16: Only event tickets can be booked today. Direct-call listings do not count. | G16: 46296 | H16: 46387 | I16: See TBO-KR2.1, PG-KR1.2 and PG-KR1.3
A17: CO-KR3.3 | B17: The Ember2Remember calendar is live by 31 October and lists what is happening in Lagos, Abuja, Enugu, Kano, Ibadan, Abia State and Rivers State, updated daily. PR publicises it on owned, partner and MTN channels through December, with a tracked link on every placement. | C17: Outcome — co-owned | D17: Branding & Marketing (PR, owner) / Partnership & Growth (fills the calendar) | E17: TBO-KR3.2; BM-KR2.2; PG-KR3.2 | F17: New measure. Events per city [TBC] from the October count. | G17: 46296 | H17: 46387 | I17: See BM-KR2.2 and PG-KR3.2
A18: CO-O4 Turn new users into repeat users. | N18: =IFERROR(ROUND(AVERAGE(N19:N22),2),"") | O18: =IFERROR(ROUND(AVERAGE(O19:O22),2),"") | P18: =IFERROR(ROUND(AVERAGE(P19:P22),2),"")
A19: CO-KR4.1 | B19: At least 40% [TBC] of users who install in November and December complete a first qualifying action within 7 days. | C19: Outcome — contingent on TBO-KR2.3 | D19: Branding & Marketing | E19: TBO-KR2.3; BM-KR1.1 | F19: Baseline from the first two weeks of analytics data. If the tool slips, count only transaction actions (ticket, payment, booking) from backend records. | G19: 46327 | H19: 46387 | I19: See BM-KR1.1 | J19: BM-KR1.1 | K19: =IF('Branding & Marketing'!I7="","",'Branding & Marketing'!I7) | L19: =IF('Branding & Marketing'!J7="","",'Branding & Marketing'!J7) | M19: =IF('Branding & Marketing'!K7="","",'Branding & Marketing'!K7) -> - Request data on user base | N19: =IF('Branding & Marketing'!L7="","",'Branding & Marketing'!L7) | O19: =IF('Branding & Marketing'!M7="","",'Branding & Marketing'!M7) | P19: =IF('Branding & Marketing'!N7="","",'Branding & Marketing'!N7)
A20: CO-KR4.2 | B20: At least 30% [TBC] of users first activated in November complete another qualifying action in December. | C20: Outcome — contingent on TBO-KR2.3 | D20: Branding & Marketing | E20: TBO-KR3.1; BM-KR1.2 | F20: Replaces the 60% 90-day target for Q4; that standard applies from Q1 2027 cohorts | G20: 46327 | H20: 46387 | I20: See BM-KR1.2 | J20: BM-KR1.2 | K20: =IF('Branding & Marketing'!I8="","",'Branding & Marketing'!I8) | L20: =IF('Branding & Marketing'!J8="","",'Branding & Marketing'!J8) | M20: =IF('Branding & Marketing'!K8="","",'Branding & Marketing'!K8) | N20: =IF('Branding & Marketing'!L8="","",'Branding & Marketing'!L8) | O20: =IF('Branding & Marketing'!M8="","",'Branding & Marketing'!M8) | P20: =IF('Branding & Marketing'!N8="","",'Branding & Marketing'!N8)
A21: CO-KR4.3 | B21: December monthly active users across both apps reach the verified September figure plus 40,000, driven by at least 64,000 new users activated in Q4 (BM-KR1.3). | C21: Outcome | D21: Branding & Marketing | E21: BM-KR1.3; BM-KR4.1; PG-KR3.1 | F21: 10% of the 400K reference. Users activated in October and November do not all return in December: at a 30% month-2 return, +40,000 needs about 64,000 activations and about 160,000 verified downloads at a 40% activation rate (Q4 Target Build). September baseline [TBC] from backend records. | G21: 46296 | H21: 46387 | I21: Function contributions add up to 64,000 activated users, over 16,000 of them from MTN channels (BM-KR4.1)
A22: CO-KR4.4 | B22: From 1 November, no customer receives more than 3 promotional push notifications a week, and promotional messages go only to users who have opted in. | C22: Compliance, floor → KPI from Q1 | D22: Branding & Marketing | E22: TBO-KR2.1; BM-K15; BM-K08 | F22: Management has observed about 300 push notifications a day on one device | G22: 46296 | H22: 46387 | I22: Measured by BM-K15 and BM-K08; caps and preference centre built under TBO-KR2.1
A23: CO-O5 Deliver Q4 revenue across all revenue streams. | N23: =IFERROR(ROUND(AVERAGE(N24:N25),2),"") | O23: =IFERROR(ROUND(AVERAGE(O24:O25),2),"") | P23: =IFERROR(ROUND(AVERAGE(P24:P25),2),"")
A24: CO-KR5.1 | B24: Q4 platform revenue earned from 1 October to 31 December reaches ₦163.3 million: advertising and brand partnerships ₦50m, events and ticketing ₦30m, payments ₦50m [TBC], enterprise and government ₦30m, and other (stays and restaurant reservations, live from 30 November) ₦3.3m. This is 10% of each stream's plan-year reference; the remaining ₦30m of the ₦200 million Q4 share waits on the CEO allocating the unassigned ₦300 million. | C24: Outcome | D24: Partnership & Growth | E24: PG-KR1.2; PG-KR1.3; PG-KR2.1; PG-KR2.2; PG-KR2.3; PG-KR2.4 | F24: Q4 is 10% of ₦2 billion plan-year revenue: ₦200 million earned in Q4 (an ₦800 million annualised rate). The payments line needs about 100,000 completed payments at the reference ₦500 each, against roughly 1,200 at today's reported run rate; locked or lowered on 7 Nov. Wallet funding and funds payable to partners are excluded. | G24: 46296 | H24: 46387 | I24: See Q4 Target Build; streams owned by PG-KR2.1, PG-KR2.3, PG-KR2.4, CO-KR5.2, PG-KR1.2 and PG-KR1.3
A25: CO-KR5.2 | B25: Completed bill, LASG and in-restaurant payments in Q4 reach [TBC] (the 10% reference is 100,000 payments and ₦2.5 billion payment value), earning the payments line of CO-KR5.1. LASG payments are live in MyLagosApp by 15 November, and December LASG platform fees are settled and reconciled to Alpha Beta records by 10 January. | C25: Outcome — co-owned; target locked 7 Nov | D25: Partnership & Growth (agreement) / Technology & Back-office Ops (integration) | E25: TBO-KR1.1; TBO-KR2.1; PG-KR2.2 | F25: About 300–400 payments a month today (unverified). Target set from the CO-KR1.1 baseline and the LASG go-live date by 7 Nov. | G25: 46296 | H25: 46397 | I25: See PG-KR2.2, TBO-KR1.1 and TBO-KR2.1
A26: CO-O6 Make on-time delivery of commitments the norm. | N26: =IFERROR(ROUND(AVERAGE(N27:N28),2),"") | O26: =IFERROR(ROUND(AVERAGE(O27:O28),2),"") | P26: =IFERROR(ROUND(AVERAGE(P27:P28),2),"")
A27: CO-KR6.1 | B27: Each function delivers at least 80% of its CEO-approved monthly priority commitments by the original date, in November and in December. | C27: Outcome | D27: CEO (Ifeoma Mbonu) | E27: PC-KR1.2 | F27: Commitment tracking does not exist today | G27: 46296 | H27: 46387 | I27: • Run one company commitment register — from 1 Oct • Each function head submits monthly commitments with acceptance criteria; the CEO approves them by the 3rd business day — function heads, monthly • Monthly review of missed items with a recovery owner and date. Deadlines are never reset; approved scope changes are shown separately — CEO, monthly
A28: CO-KR6.2 | B28: By 15 December, every employee has a signed scorecard, and October and November reviews scored from actual results are complete. | C28: Enabling / compliance, retiring | D28: People & Culture | E28: PC-KR1.1 | F28: Framework in progress | G28: 46296 | H28: 46371 | I28: See PC-KR1.1 | J28: PC-KR1.1 | K28: =IF('People & Culture'!I7="","",'People & Culture'!I7) | L28: =IF('People & Culture'!J7="","",'People & Culture'!J7) | M28: =IF('People & Culture'!K7="","",'People & Culture'!K7) | N28: =IF('People & Culture'!L7="","",'People & Culture'!L7) | O28: =IF('People & Culture'!M7="","",'People & Culture'!M7) | P28: =IF('People & Culture'!N7="","",'People & Culture'!N7)

Sheet Technology & Back-office Ops
A1: Technology & Back-office Ops OKRs
A2: MyCityApp and MyLagosApp · Q4 2026 (Oct–Dec) · Foundation draft for review · Function head: Bode Oluwasanmi (CTO)
A3: Makes payments, tickets and bookings work, ships the capabilities and measurement the business depends on, keeps what customers see in all three apps (MyLagosApp, MyCityApp Nigeria, MyCityApp Africa) current and correct, and runs customer support. Development is delivered through MTNN.
I4: Latest — updated at each monthly report | L4: Score by month
A5: KR ID | B5: Key result | C5: Type | D5: Initiatives (date) | E5: Accountable owner | F5: Linked company KR | G5: Start | H5: Finish | I5: Status | J5: Actual | K5: Update | L5: October | M5: November | N5: December · Q4 final
A6: TBO-O1 Make payments, tickets, bookings and support reliable. | L6: =IFERROR(ROUND(AVERAGE(L7:L9),2),"") | M6: =IFERROR(ROUND(AVERAGE(M7:M9),2),"") | N6: =IFERROR(ROUND(AVERAGE(N7:N9),2),"")
A7: TBO-KR1.1 | B7: Bill-payment and LASG-payment success is at least 95% in December, measured daily, with no day below 90%. | C7: Outcome | D7: • Root-cause the top five failure reasons from September–October provider logs — 15 Oct • Daily success-rate monitor with an alert below 90% — 31 Oct • Fixes, safe retries and a controlled refund path delivered with MTNN — 15 Nov | E7: Bode Oluwasanmi | F7: CO-KR2.1; CO-KR5.2 | G7: 46296 | H7: 46387 | I7: On track | K7: Measurement approach available. Service adoption low. So no real traffic.
A8: TBO-KR1.2 | B8: At least 97% of valid ticket-purchase attempts in Q4 result in a valid ticket, with zero duplicate charges and zero oversold events. | C8: Outcome | D8: • BlueSalt API v2 upgrade and simplified checkout released (P0) — 15 Nov • Load test ticketing for the five largest December events — 30 Nov • Change freeze on payment, ticket and wallet journeys — 15 Dec to 5 Jan | E8: Bode Oluwasanmi | F8: CO-KR2.2 | G8: 46296 | H8: 46387 | I8: On track | K8: Blue salt upgrade upgrade done. Pending go-live. Temporary freeze on MTNN. - TBD.
A9: TBO-KR1.3 | B9: Customer support is live by 15 November on the published channels, with a case log. At least 85% of December cases are resolved within 48 hours, including refund and booking cases handled with partners or providers. | C9: Enabling → Outcome | D9: • Support playbook for failed payments, missing tickets, booking changes and refunds — 5 Nov • Case log with timestamps and escalation to the development team (MTNN) and Partnership & Growth — 10 Nov • Staffed December rota covering the peak event days — 1 Dec | E9: Oladotun Shola Adido | F9: CO-KR2.3 | G9: 46296 | H9: 46341 | I9: On track | K9: Ifeoma's TA hiring - Cynthia (Interviews in progress) Recommend Support Ticket Desk - Bode. Explore the ERP solution development/implementation in progress.
A10: TBO-O2 Ship Q4 capabilities on time without breaking live services. | L10: =IFERROR(ROUND(AVERAGE(L11:L13),2),"") | M10: =IFERROR(ROUND(AVERAGE(M11:M13),2),"") | N10: =IFERROR(ROUND(AVERAGE(N11:N13),2),"")
A11: TBO-KR2.1 | B11: Every Q4 committed capability is live in MyLagosApp and MyCityApp on its date and accepted by its acceptance owner: . | C11: Output — enabling; retires on release | D11: • CEO-approved roadmap with an MTNN delivery month and an acceptance owner for every item — CEO, 15 Oct • Weekly MTNN delivery review; slipped items escalated within 2 business days (TBO-K15) — weekly • In-store payment user stories, restaurants first; decide whether the merchant collection web app is needed for launch — CEO, 20 Oct • FAAN scope, airports and operator integration agreed — 20 Oct • Notification caps, separate transactional and promotional messages, preference centre — 31 Oct • Alpha Beta integration and UAT; staff and pilot launch before public launch — 31 Oct • Redesign approved against the Brand Book (BM-KR3.1) — 31 Oct • Stays and restaurant booking on the ticketing checkout, with back-office confirmation queues — 20 Nov • End-to-end tests with five signed hotels and five signed restaurants (PG-KR1.2, PG-KR1.3) — 28 Nov | E11: Bode Oluwasanmi | F11: CO-KR2.4; CO-KR3.2; CO-KR4.4; CO-KR5.2 | G11: 46296 | H11: 46356 | K11: Hotel booking functionality - in progress Merchant Payment - Next sprint (Design completed) Restaurant Payment - Next Sprint (Design completed) UX/UI - Ongoing (EOY) Pending conversation on FAAN Airport taxi booking on commission. Share the designs for Wallet-to-Wallet Payment - Bode.
A12: TBO-KR2.2 | B12: No Q4 release degrades what already works: in the 14 days after each release, bill-payment and ticket success are no lower than in the 14 days before, and no customer-affecting P1 incident is caused by a release. | C12: Outcome — quality guard | D12: • Technical, business and service-owner approval recorded for every priority release (TBO-K06) — from 15 Oct • Rollback plan tested for each P0 release — 25 Nov • Staged rollout of the redesign and new journeys: staff, then 10% of users, then everyone — 30 Nov • December change freeze, 15 Dec to 5 Jan — CEO | E12: Bode Oluwasanmi | F12: CO-KR2.1; CO-KR2.2 | G12: 46296 | H12: 46387
A13: TBO-KR2.3 | B13: A product analytics tool (e.g. Mixpanel or Amplitude) is contracted by 15 October and records seven priority journeys in both apps by 15 November: install, first qualifying action, ticket purchase, bill payment, LASG payment, business contact and booking request. The November figures reconcile to provider and settlement records within 2%. | C13: Visibility gate — retires after two reconciled months | D13: • Compare product analytics tools on cost, SDK fit and data export; recommend one to the CEO — 8 Oct • Contract the tool and approve the event dictionary (names, properties, qualifying-action definition) — 15 Oct • Capture a partner, event or MTN channel code at sign-up in the backend — 15 Oct • Interim weekly report from backend and provider records until the tool is live — from 12 Oct • Instrument the journeys through MTNN — 10 Nov • First reconciled monthly report — 5 Dec | E13: Bode Oluwasanmi | F13: CO-KR1.1; CO-KR1.2; CO-KR4.1 | G13: 46296 | H13: 46361 | K13: Pending Review/tool identification
A14: TBO-O3 Keep app content accurate and publish new supply fast. | L14: =IFERROR(ROUND(AVERAGE(L15:L17),2),"") | M14: =IFERROR(ROUND(AVERAGE(M15:M17),2),"") | N14: =IFERROR(ROUND(AVERAGE(N15:N17),2),"")
A15: TBO-KR3.1 | B15: At least 98% of audited live events, stays and business listings in each of the three apps pass date, price, location and contact checks in December. The October audit sets the baseline. | C15: Outcome — target provisional until the October audit | D15: • Baseline audit per app with a documented sampling method — 25 Oct • Pre-publication checks per content type — 15 Nov • Automatic expiry of one-off events at their end time, dated in the roadmap; daily manual expiry check until then (TBO-K09) — roadmap date • Verify hospital, police and fire-service contacts against official sources — 30 Nov | E15: Oladotun Shola Adido | F15: CO-KR4.2 | G15: 46296 | H15: 46387 | K15: - Auto-deletion of expired events. - Confirm why it is not running - Shola/Bode - Live notification for events(countdown timers, etc.) - Engage Shola for a walkthrough on the event management capability on myCityApp Admin console.
A16: TBO-KR3.2 | B16: 95% of complete, approved submissions for events, stays and business profiles are published within 2 business days in November and December. | C16: Outcome | D16: • One publishing queue with required fields, owner and deadline — 20 Oct • Daily upload of Ember2Remember calendar events from Partnership & Growth’s submissions, reported to the CTO (TBO-K14) — daily from 1 Nov • Return incomplete submissions with the missing items named — ongoing | E16: Oladotun Shola Adido | F16: CO-KR3.1; CO-KR3.2; CO-KR3.3 | G16: 46296 | H16: 46387
A17: TBO-KR3.3 | B17: At least 5,000 new business profiles are published in MyCityApp in Q4, owner-verified and with all required fields. They include restaurants, hotels and tourist locations in Lagos, Abuja, Enugu, Kano, Ibadan, Abia State, Rivers State and the other major cities; tourist locations are verified against official sources and published under SeeNaija. Partnership & Growth supplies association and partner lists; Operations verifies and publishes. | C17: Output | D17: • Verification call script and required-field standard — 15 Oct • City targets for restaurants, hotels and tourist locations — 20 Oct • Tourist-location discovery across all Nigerian cities, published under SeeNaija — from 1 Nov • Bulk listing upload, dated in the roadmap; manual batches until then — from 1 Nov | E17: Oladotun Shola Adido | F17: CO-O3 (verified businesses; no company KR) | G17: 46296 | H17: 46387
A19: Operational KPIs
A20: Recurring measures of how well the function runs, each with one formula, a target and a data source. No KPI repeats a KR. No eligible cases means N/A, not 100%. Overdue cases stay in the denominator. Record each month’s actual; KPIs are not scored.
A21: KPI ID | B21: KPI | C21: Formula | D21: Unit | E21: Direction | F21: Target | G21: Frequency | H21: Data source | I21: Result | J21: Actual | K21: Comment | L21: October | M21: November | N21: December
A22: TBO-K01 | B22: Payment and ticketing service availability rate | C22: Minutes the monitored payment and ticketing services are usable ÷ total minutes in the month (planned outages count as downtime) | D22: % | E22: Higher is better | F22: ≥99.5% | G22: Monthly | H22: Uptime monitor; MTNN incident log
A23: TBO-K02 | B23: Priority-1 incident recovery rate | C23: Customer-affecting P1 incidents restored within 4 hours ÷ P1 incidents in the month | D23: % | E23: Higher is better | F23: ≥90% | G23: Monthly | H23: Incident log
A24: TBO-K03 | B24: Next-day transaction matching rate | C24: Settled transactions matched to order, provider and settlement references by the next business day ÷ settled transactions | D24: % | E24: Higher is better | F24: 100% | G24: Daily; reported monthly | H24: Reconciliation report
A25: TBO-K04 | B25: Verified backup success rate | C25: Production backups completed and verified readable ÷ backups scheduled | D25: % | E25: Higher is better | F25: 100% | G25: Daily; reported monthly | H25: Backup log
A26: TBO-K05 | B26: Overdue production-access removals | C26: Number of departed or unauthorised users still holding production access after the removal cut-off | D26: Count | E26: Lower is better | F26: 0 | G26: Monthly maximum | H26: Access register; P&C exit list
A27: TBO-K06 | B27: Release approval compliance rate | C27: Priority releases with recorded technical, business and service-owner approval ÷ priority releases | D27: % | E27: Higher is better | F27: 100% | G27: Per release; reported monthly | H27: Release log
A28: TBO-K07 | B28: Campaign-link accuracy rate | C28: Campaign links reaching the correct in-app item on installed and new-install journeys ÷ campaign links tested | D28: % | E28: Higher is better | F28: 100% | G28: Before each launch; reported monthly | H28: Pre-launch test log
A29: TBO-K08 | B29: Event expiry compliance rate | C29: One-off events removed from upcoming listings within 24 hours of their end time ÷ events due for removal | D29: % | E29: Higher is better | F29: ≥98% | G29: Monthly, per app | H29: Listing audit; admin log
A30: TBO-K09 | B30: Stale events on display | C30: Highest daily count of events still shown as upcoming 7+ days after they ended | D30: Count | E30: Lower is better | F30: 0 | G30: Daily; monthly maximum | H30: Daily listing check
A31: TBO-K10 | B31: Listing correction turnaround rate | C31: Confirmed listing errors corrected or withdrawn within 1 business day ÷ errors due | D31: % | E31: Higher is better | F31: ≥95% | G31: Monthly | H31: Correction log
A32: TBO-K11 | B32: Unresolved critical contact errors | C32: Confirmed wrong hospital, police or fire-service entries not yet corrected or hidden | D32: Count | E32: Lower is better | F32: 0 | G32: Monthly maximum | H32: Correction log
A33: TBO-K12 | B33: Business profile completeness rate | C33: Published profiles with all required location, category, service and contact fields ÷ profiles audited | D33: % | E33: Higher is better | F33: ≥95% | G33: Monthly | H33: Listing audit
... A36: TBO-K15 | B36: MTNN milestone on-time acceptance rate | C36: Roadmap milestones accepted by their acceptance owner by the committed date ÷ milestones due | D36: % | E36: Higher is better | F36: ≥80% | G36: Monthly | H36: Roadmap; MTNN delivery log
A37: Baselines for every KPI come from CO-KR1.1 (31 October). Data sources are records available today; none depends on the analytics tool unless stated.

Sheet Branding & Marketing
A1: Branding & Marketing OKRs
A2: MyCityApp and MyLagosApp · Q4 2026 (Oct–Dec) · Foundation draft for review · Function head: Chinyere Elechi
A3: Gets the right people into the apps, makes their first week worthwhile, sells December's events and sends only the messages customers asked for.
I4: Latest — updated at each monthly report | L4: Score by month
A5: KR ID | B5: Key result | C5: Type | D5: Initiatives (date) | E5: Accountable owner | F5: Linked company KR | G5: Start | H5: Finish | I5: Status | J5: Actual | K5: Update | L5: October | M5: November | N5: December · Q4 final
A6: BM-O1 Activate new users and bring them back. | L6: =IFERROR(ROUND(AVERAGE(L7:L9),2),"") | M6: =IFERROR(ROUND(AVERAGE(M7:M9),2),"") | N6: =IFERROR(ROUND(AVERAGE(N7:N9),2),"")
A7: BM-KR1.1 | B7: At least 40% [TBC] of users who install in November and December complete a first qualifying action within 7 days, through welcome journeys live by 15 November for each source (partner-event sign-up, LASG payer, MTN channel, organic, paid campaign). | C7: Outcome — contingent on TBO-KR2.3 | D7: • Lifecycle lead named for activation, welcome journeys and cohort review — CEO, 25 Sep • Map the first action that fits each source (e.g. event sign-up → next event ticket; LASG payer → saved bill reminder) — 25 Oct • Build the in-app and message sequences with Technology & Back-office Ops — 12 Nov • Weekly cohort review; change the weakest journey each fortnight — from 20 Nov | E7: Chinyere Elechi | F7: CO-KR4.1 | G7: 46327 | H7: 46387 | K7: - Request data on user base
A8: BM-KR1.2 | B8: At least 30% [TBC] of users first activated in November complete another qualifying action in December. | C8: Outcome — contingent on TBO-KR2.3 | D8: • Audit all automated and manual push campaigns; switch off duplicates — 20 Oct • One approved send calendar; every send has an audience, cap check and owner (BM-K15) — 31 Oct • Weekly digest, including the Ember2Remember calendar, replaces single-offer pushes for opted-in users — 15 Nov • Retarget ticket buyers and stay guests for nearby events and next stays (opted-in users only) — December | E8: Chinyere Elechi | F8: CO-KR4.2 | G8: 46327 | H8: 46387
A9: BM-KR1.3 | B9: At least 64,000 new users from all channels (marketing campaigns, MTN channels, partner placements and event sign-ups) complete a first qualifying action within 7 days in Q4, at or below the approved cost per activated user. | C9: Outcome | D9: • December marketing plan and advertising budget approved, through media buyers checked against our brand and values, including Tochi’s Grow app as a channel — CEO, 31 Oct • Convert partner-placement and event sign-ups through the welcome journey within 24 hours of hand-over — from 1 Nov • Creator guides for December events and stays, linking to the in-app item — from 1 Nov • LASG payment awareness by payer group (Land Use Charge, water, waste) once live — from 15 Nov • Reallocate spend every two weeks towards cost per activated user (BM-K07) — fortnightly | E9: Chinyere Elechi | F9: CO-KR4.3 | G9: 46296 | H9: 46387
A10: BM-O2 Drive December ticket sales. | L10: =IFERROR(ROUND(AVERAGE(L11:L13),2),"") | M10: =IFERROR(ROUND(AVERAGE(M11:M13),2),"") | N10: =IFERROR(ROUND(AVERAGE(N11:N13),2),"")
A11: BM-KR2.1 | B11: At least ₦100 million of Q4 paid-ticket value, 40% of the ₦250 million in CO-KR3.1, comes through Marketing campaigns, tracked from campaign link to paid ticket. | C11: Outcome | D11: • Promote the Ember2Remember calendar events — from 31 Oct • Organiser co-promotion and creator previews for the 25 exclusive December events — from 15 Nov • Retarget ticket buyers for their next event (opted-in users only) — December | E11: Chinyere Elechi | F11: CO-KR3.1 | G11: 46296 | H11: 46387 | K11: 6 paid events - MOU shared Kano Polo Club - Revisit the Partnership.
A12: BM-KR2.2 | B12: PR publicises the Ember2Remember calendar from 31 October through December: at least [TBC] earned-media, creator, partner and MTN-channel placements, each with a tracked link to the calendar. | C12: Outcome | D12: • Calendar format, city sections and publishing rules — 15 Oct • PR plan: press, creators, partner and MTN channels — 25 Oct • Calendar live in the apps, filled by Partnership & Growth (PG-KR3.2) and uploaded daily (TBO-KR3.2) — 31 Oct | E12: Chinyere Elechi | F12: CO-KR3.3 | G12: 46296 | H12: 46387 | K12: BeatFm, TV Interviews, Radio Interview, Ember2Remember Song - Memorable experiential content directions - Partnership with event organisers for promotion - Leverage Providus Bank for publicity - MTN - Revise the content direction and budget
A13: BM-KR2.3 | B13: At least 10 promoters and organisers of calendar events, starting with Showrunner, sell their tickets through MyCityApp in Q4 and feature MyCityApp on their promotional materials (logo, QR code or tracked link). | C13: Outcome | D13: • Showrunner adds MyCityApp as a ticket vending platform and carries it on their promotional materials — with Partnership & Growth, 20 Oct • Co-branding kit for promoters (logo, QR code, tracked link, usage rules) — 20 Oct • Promoter materials checked against the Brand Book before release — per event | E13: Chinyere Elechi | F13: CO-KR3.1 | G13: 46296 | H13: 46387
A14: BM-O3 Give each app a distinct, consistent brand. | L14: =IFERROR(ROUND(AVERAGE(L15:L16),2),"") | M14: =IFERROR(ROUND(AVERAGE(M15:M16),2),"") | N14: =IFERROR(ROUND(AVERAGE(N15:N16),2),"")
A15: BM-KR3.1 | B15: The Brand Book is approved by the CEO by 31 October, covering positioning, audience, voice, naming rules and visual identity for MyLagosApp, MyCityApp Nigeria and MyCityApp Africa. | C15: Enabling — retires on approval | D15: • Positioning and message architecture for the three apps — 10 Oct • Visual system, templates and asset library — 24 Oct • CEO approval — CEO, 31 Oct | E15: Chinyere Elechi | F15: CO-O4 (no company KR) | G15: 46296 | H15: 46326
A16: BM-KR3.2 | B16: By 15 December, every app-store page, website and social profile of the three apps conforms to the Brand Book, and 100% of new campaign assets pass the brand check from 1 November. | C16: Compliance, floor → BM-K09 from Q1 | D16: • Re-skin app-store pages and social profiles for MyLagosApp, MyCityApp Nigeria and MyCityApp Africa — 15 Dec • Brand check on every paid asset and a sample of organic assets (BM-K09) — from 1 Nov • Redesigned apps apply the Brand Book (TBO-KR2.1) — 30 Nov | E16: Chinyere Elechi | F16: CO-O4 (no company KR) | G16: 46296 | H16: 46371
A17: BM-O4 Grow users through MTN and launch SeeNaija tourism. | L17: =IFERROR(ROUND(AVERAGE(L18:L19),2),"") | M17: =IFERROR(ROUND(AVERAGE(M18:M19),2),"") | N17: =IFERROR(ROUND(AVERAGE(N18:N19),2),"")
A18: BM-KR4.1 | B18: MTN channels deliver more than 16,000 of BM-KR1.3's 64,000: new users who complete a first qualifying action after arriving through MTN SMS, the MTN app, MTN shops and service centres, or MTN airport stands, each tracked by its own channel code. | C18: Outcome | D18: • Map the MTN partnership across departments (digital marketing, marketing activation, retail, SeeNaija) with a named MTN contact for each — 15 Oct • SMS blasts one week each month, 3 slots a month, under MTN’s consent rules with an opt-out (BM-K08) — monthly from Oct • MTN app advertising and a joint activation calendar with MTN’s marketing department — 31 Oct • In-store activations at MTN shops and service centres, and MTN airport stands: assisted download and first action — from 1 Nov | E18: Chinyere Elechi | F18: CO-KR4.3 | G18: 46296 | H18: 46387 | K18: Digital Marketing - In-app ads, SMS, app growth Marketing - - SeeNaija - Working with the marketing (where MTN is a sponsor and all event MTNN is in collaboration) - Y'ello tidings - Explore your city redirects to mycityapp.io
A19: BM-KR4.2 | B19: SeeNaija, MTNN's tourism initiative, becomes the tourism feature in MyCityApp. The SeeNaija partnership terms with MTNN are agreed by 31 October, and at least [TBC] tourism packages curated with Kayode Okikiolu and TourGuide are live in the app by 15 December. | C19: Output — enabling | D19: • Agree SeeNaija scope, branding and roles with MTNN — 31 Oct • Package design with Kayode Okikiolu (kayodeokikiolu.com) and TourGuide — 20 Nov • Tourist locations listed under SeeNaija by back-office Ops (TBO-KR3.3) — from 1 Nov • SeeNaija launch campaign — 15 Dec | E19: Chinyere Elechi | F19: CO-O3 (no company KR) | G19: 46296 | H19: 46371
A21: Operational KPIs
A22: Recurring measures of how well the function runs, each with one formula, a target and a data source. No KPI repeats a KR. No eligible cases means N/A, not 100%. Overdue cases stay in the denominator. Record each month’s actual; KPIs are not scored.
A23: KPI ID | B23: KPI | C23: Formula | D23: Unit | E23: Direction | F23: Target | G23: Frequency | H23: Data source | I23: Result | J23: Actual | K23: Comment | L23: October | M23: November | N23: December
A24: BM-K01 | B24: Content calendar coverage | C24: Consecutive future days covered by approved content with channel, date and owner | D24: Days | E24: Higher is better | F24: ≥28 | G24: Weekly check; monthly minimum | H24: Content calendar
A25: BM-K02 | B25: On-time publication rate | C25: Scheduled posts published at the agreed time ÷ posts due (approved cancellations shown separately) | D25: % | E25: Higher is better | F25: ≥95% | G25: Monthly | H25: Content calendar; channel logs
A26: BM-K03 | B26: On-time creative asset delivery rate | C26: Campaign assets delivered by the agreed deadline ÷ assets due | D26: % | E26: Higher is better | F26: ≥95% | G26: Monthly | H26: Creative request tracker
A27: BM-K04 | B27: Creative first-pass approval rate | C27: First submissions approved without substantial rework against the brief ÷ first submissions | D27: % | E27: Higher is better | F27: ≥85% | G27: Monthly | H27: Creative request tracker
A28: BM-K05 | B28: Campaign attribution coverage rate | C28: Live campaigns with a working link to the promoted item and first-action tracking ÷ live campaigns | D28: % | E28: Higher is better | F28: 100% | G28: Monthly | H28: Campaign register
A29: BM-K06 | B29: Campaign budget variance | C29: (Actual + committed spend − approved cap) ÷ approved cap; no approved cap means no spending authority | D29: % | E29: Lower is better | F29: ≤0% | G29: Per campaign; monthly | H29: Campaign register; finance records
A30: BM-K07 | B30: Cost per activated user | C30: Campaign spend ÷ new users completing a first qualifying action attributed to the campaign | D30: ₦ | E30: Lower is better | F30: ≤ approved ceiling | G30: Per campaign; monthly | H30: Campaign register; analytics (backend records until live)
A31: BM-K08 | B31: Marketing consent violations | C31: Promotional push or SMS sends without valid consent, after opt-out, or beyond the user's chosen frequency (includes SMS sent through MTN) | D31: Count | E31: Lower is better | F31: 0 | G31: Monthly | H31: Messaging tool logs; MTN SMS delivery reports
A32: BM-K09 | B32: Brand compliance rate — new assets | C32: New published assets passing Brand Book, price, date and claim checks ÷ new assets checked (all paid, sample of organic) | D32: % | E32: Higher is better | F32: 100% | G32: Monthly from 1 Nov | H32: Brand review log
A33: BM-K10 | B33: Social enquiry response rate | C33: Social enquiries answered or routed to the owning team within 1 business day ÷ enquiries received | D33: % | E33: Higher is better | F33: ≥90% | G33: Monthly | H33: Social inbox
A34: BM-K11 | B34: Social-to-app click-through rate | C34: Clicks on tracked app links from organic social posts ÷ reach of those posts (per 1,000) | D34: Clicks per 1,000 reach | E34: Higher is better | F34: [TBC] — October baseline + 20% | G34: Monthly | H34: Link shortener or UTM report; platform insights (no app analytics needed)
A35: BM-K12 | B35: Earned-media placements | C35: Published media or partner-channel pieces naming the app and a specific service | D35: Count | E35: Higher is better | F35: ≥4 a month [TBC] | G35: Monthly | H35: Press log with links
... A39: BM-K16 | B39: Push opt-out rate | C39: Users switching off promotional push in the month ÷ users opted in at the start of the month | D39: % | E39: Lower is better | F39: <2% [TBC] | G39: Monthly | H39: Messaging tool logs; preference centre
A40: Baselines for every KPI come from CO-KR1.1 (31 October). Data sources are records available today; none depends on the analytics tool unless stated.

Sheet Partnership & Growth
A1: Partnership & Growth OKRs
A2: MyCityApp and MyLagosApp · Q4 2026 (Oct–Dec) · Foundation draft for review · Function head: Abubakar Mohammed (Head of Partnership once hired)
A3: Puts events, stays and deals on the platform on terms that pay MyCityApp and give customers something exclusive, and brings in partner users who stay.
I4: Latest — updated at each monthly report | L4: Score by month
A5: KR ID | B5: Key result | C5: Type | D5: Initiatives (date) | E5: Accountable owner | F5: Linked company KR | G5: Start | H5: Finish | I5: Status | J5: Actual | K5: Update | L5: October | M5: November | N5: December · Q4 final
A6: PG-O1 Secure festive-season events, stays and restaurants on profitable, exclusive terms. | L6: =IFERROR(ROUND(AVERAGE(L7:L9),2),"") | M6: =IFERROR(ROUND(AVERAGE(M7:M9),2),"") | N6: =IFERROR(ROUND(AVERAGE(N7:N9),2),"")
A7: PG-KR1.1 | B7: At least 200 ticketed events are live in Q4 under signed commission terms. At least 25 of the December events carry an app-exclusive allocation, price or access benefit. | C7: Outcome | D7: • Festive-season pipeline: concerts, comedy, festivals and conferences with ticket-sales history — 15 Oct • Showrunner and other calendar promoters sign MyCityApp as a ticket vending platform (with BM-KR2.3) — 20 Oct • Exclusive-terms offer (allocation, early access, bundled stay) for top organisers — 31 Oct • Signed events handed to back-office Ops as complete submissions — per signature | E7: Abubakar Mohammed | F7: CO-KR3.1 | G7: 46296 | H7: 46387
A8: PG-KR1.2 | B8: At least 150 hotels and shortlets across Lagos, Abuja, Enugu, Kano, Ibadan, Abia State and Rivers State (at least [TBC] in Lagos) have signed terms by 20 November, and 250 by 31 December: December bookable inventory in MyLagosApp and MyCityApp, confirmation within 2 hours, platform fee and an app-exclusive benefit. | C8: Enabling — retires once bookings run at scale | D8: • Target list by city, area and event proximity — 10 Oct • Standard partner terms and fee approved — CEO, 20 Oct • Abuja signings and city leads for Enugu, Kano, Ibadan, Abia State and Rivers State — from 15 Oct • Five launch partners ready to test the booking flow — 25 Nov | E8: Abubakar Mohammed | F8: CO-KR3.2; CO-KR5.1 | G8: 46296 | H8: 46387
A9: PG-KR1.3 | B9: At least 150 restaurants across Lagos, Abuja, Enugu, Kano, Ibadan, Abia State and Rivers State have signed terms by 20 November covering table booking and in-restaurant payment, so both launch on 30 November with live inventory. | C9: Enabling — retires once bookings run at scale | D9: • Restaurant terms (slot booking, deposit rule, in-restaurant payment fee, exclusive benefit) approved — CEO, 25 Oct • Five launch restaurants ready to test booking and payment — 25 Nov • Signed restaurants handed to back-office Ops for profile readiness — per signature | E9: Abubakar Mohammed | F9: CO-KR2.4; CO-KR3.2; CO-KR5.1 | G9: 46296 | H9: 46346
A10: PG-O2 Grow Q4 partner revenue. | L10: =IFERROR(ROUND(AVERAGE(L11:L14),2),"") | M10: =IFERROR(ROUND(AVERAGE(M11:M14),2),"") | N10: =IFERROR(ROUND(AVERAGE(N11:N14),2),"")
A11: PG-KR2.1 | B11: ₦50 million [TBC] in advertising and brand-partnership revenue is earned in Q4 from campaigns delivered in the apps and advertising slots on the MyCityApp website: 10% of the ₦500 million plan-year reference. | C11: Outcome | D11: • Festive sponsorship packages (city guides, event categories, homepage) priced with delivery costs — 20 Oct • MyCityApp website ad slots: slot inventory, rate card and booking process, sold to interested advertisers — 31 Oct • Qualified pipeline at 3× the Q4 target (₦150 million) (PG-K01) — 31 Oct • Client customer-action targets agreed with Marketing before signature (BM-K14) — per campaign | E11: Abubakar Mohammed | F11: CO-KR5.1 | G11: 46296 | H11: 46387
A12: PG-KR2.2 | B12: The Alpha Beta/LASG agreement is signed by 15 October, covering bill types, platform fee, settlement and refund responsibilities, and December LASG platform fees are invoiced and reconciled to Alpha Beta records by 10 January. | C12: Enabling → Outcome | D12: • Close outstanding commercial terms — 10 Oct • Agreed bill types and fees handed to Technology & Back-office Ops and Marketing — 17 Oct • December fee invoice and reconciliation with Alpha Beta, with Technology & Back-office Ops — 10 Jan | E12: Abubakar Mohammed | F12: CO-KR5.1; CO-KR5.2 | G12: 46296 | H12: 46397
A13: PG-KR2.3 | B13: ₦30 million [TBC] in ticketing revenue is earned in Q4 from signed events, 10% of the ₦300 million plan-year reference: contracted rates averaging at least 12% of the ₦250 million paid-ticket value, net of refunds, credited to the account owner on the pipeline record. | C13: Outcome | D13: • Contracted commission rate recorded on every event deal; deals below 10% need CEO approval (PG-K07) — per signature • Exclusive-terms offers priced so the exclusive benefit does not cut the platform rate — 31 Oct • Event close-out reconciliation of tickets, refunds, commission and organiser payout, with Technology & Back-office Ops — within 5 business days of each event | E13: Abubakar Mohammed | F13: CO-KR3.1; CO-KR5.1 | G13: 46296 | H13: 46387
A14: PG-KR2.4 | B14: ₦30 million [TBC] in enterprise and government partnership revenue is contracted and invoiced in Q4, 10% of the ₦300 million plan-year reference: state digital integrations, tourism, corporate concierge and destination marketing. | C14: Outcome | D14: • Named pipeline of state, tourism and corporate accounts at 3× the target (₦90 million) — 31 Oct • State collections proposals for Enugu, Cross River, Akwa Ibom, Benue and Plateau — 15 Nov • Destination-marketing packages with SeeNaija (BM-KR4.2) — 30 Nov • Only signed contracts and issued invoices count — monthly | E14: Abubakar Mohammed | F14: CO-KR5.1 | G14: 46296 | H14: 46387
A15: PG-O3 Fill the Ember2Remember calendar and extend its reach through partners. | L15: =IFERROR(ROUND(AVERAGE(L16:L17),2),"") | M15: =IFERROR(ROUND(AVERAGE(M16:M17),2),"") | N15: =IFERROR(ROUND(AVERAGE(N16:N17),2),"")
A16: PG-KR3.1 | B16: At least 30 [TBC] live distribution placements are secured in Q4 (hotel guest messages, event ticket emails, association and conference channels), each with an agreed audience and a tracked MyCityApp link that passes Technology's link test. | C16: Output — enabling | D16: • Placement offer for partners: what they get (content, exclusive benefit for their audience) and what they carry — 15 Oct • Territory placement targets agreed with each officer — 25 Sep • Each placement handed to Marketing with audience, dates and link within 2 business days of signature — per placement | E16: Abubakar Mohammed | F16: CO-KR4.3 | G16: 46296 | H16: 46387
A17: PG-KR3.2 | B17: Partnership & Growth fills the Ember2Remember calendar: from 1 November, at least [TBC] upcoming events a week are submitted for each of Lagos, Abuja, Enugu, Kano, Ibadan, Abia State and Rivers State, each handed to back-office Ops as a complete submission. | C17: Output — enabling | D17: • Event sources per city (promoters, venues, associations, government calendars) — 15 Oct • Weekly city targets agreed with each territory officer — 20 Oct • Complete submissions handed to back-office Ops for daily upload — daily from 1 Nov • Calendar ownership handed to the Head of Partnership on arrival — Nov | E17: Abubakar Mohammed (Head of Partnership once hired) | F17: CO-KR3.3 | G17: 46296 | H17: 46387
A19: Operational KPIs
A20: Recurring measures of how well the function runs, each with one formula, a target and a data source. No KPI repeats a KR. No eligible cases means N/A, not 100%. Overdue cases stay in the denominator. Record each month’s actual; KPIs are not scored.
A21: KPI ID | B21: KPI | C21: Formula | D21: Unit | E21: Direction | F21: Target | G21: Frequency | H21: Data source | I21: Result | J21: Actual | K21: Comment | L21: October | M21: November | N21: December
A22: PG-K01 | B22: Qualified pipeline coverage ratio | C22: Platform revenue expected in Q4 from qualified open opportunities ÷ remaining Q4 revenue target (excludes ticket value and GMV) | D22: Ratio | E22: Higher is better | F22: ≥3.0× | G22: Monthly | H22: Pipeline register
A23: PG-K02 | B23: On-time partner launch rate | C23: Signed partners and events live on the agreed date ÷ launches due (overdue launches stay in) | D23: % | E23: Higher is better | F23: ≥90% | G23: Monthly | H23: Pipeline register; publishing queue
A24: PG-K03 | B24: Signed-deal handover rate | C24: Signed deals accepted by the delivering team within 2 business days of signature ÷ deals signed | D24: % | E24: Higher is better | F24: ≥95% | G24: Monthly | H24: Handover log
A25: PG-K04 | B25: Partner booking confirmation rate | C25: Stay and restaurant requests confirmed or declined by the partner within 2 hours ÷ requests received | D25: % | E25: Higher is better | F25: ≥90% | G25: Weekly in December; monthly | H25: Booking back office
A26: PG-K05 | B26: On-time invoice collection rate | C26: Cash received by the invoice due date ÷ invoiced amounts due | D26: % | E26: Higher is better | F26: ≥95% | G26: Monthly | H26: Finance records
A27: PG-K06 | B27: Exclusive-offer terms documentation rate | C27: Live exclusive offers with benefit, availability, validity and redemption terms recorded ÷ live exclusive offers | D27: % | E27: Higher is better | F27: 100% | G27: Monthly | H27: Offer register
A28: PG-K07 | B28: Commercial approval-limit compliance rate | C28: Deals agreed within approved pricing and discount authority ÷ deals agreed | D28: % | E28: Higher is better | F28: 100% | G28: Monthly | H28: Deal approvals log
A29: PG-K08 | B29: Overdue sales follow-ups | C29: Qualified opportunities whose agreed next action is more than 5 business days overdue | D29: Count | E29: Lower is better | F29: 0 | G29: Weekly; monthly maximum | H29: Pipeline register
A30: Baselines for every KPI come from CO-KR1.1 (31 October). Data sources are records available today; none depends on the analytics tool unless stated.

Sheet People & Culture
A1: People & Culture OKRs
A2: MyCityApp and MyLagosApp · Q4 2026 (Oct–Dec) · Foundation draft for review · Function head: Cynthia Osakunih
A3: Gives every employee clear ownership and reviews based on results, runs the company commitment register, staffs customer support and moves core HR processes out of Excel.
I4: Latest — updated at each monthly report | L4: Score by month
A5: KR ID | B5: Key result | C5: Type | D5: Initiatives (date) | E5: Accountable owner | F5: Linked company KR | G5: Start | H5: Finish | I5: Status | J5: Actual | K5: Update | L5: October | M5: November | N5: December · Q4 final
A6: PC-O1 Hold everyone accountable for clear, measured results. | L6: =IFERROR(ROUND(AVERAGE(L7:L9),2),"") | M6: =IFERROR(ROUND(AVERAGE(M7:M9),2),"") | N6: =IFERROR(ROUND(AVERAGE(N7:N9),2),"")
A7: PC-KR1.1 | B7: October and November reviews are complete for 100% of eligible employees by 15 December, each scored from actual results against the employee's signed Q4 scorecard, with a corrective action for every missed result. | C7: Compliance, retiring → KPI in 2027 | D7: • Q4 scorecards signed by every employee and reviewer — 25 Sep • Organisation chart updated (CTO leads Technology and back-office Ops) and back-office Ops scorecards re-signed with the CTO as reviewer — CTO, 12 Oct • Review calendar and manager guidance — 20 Oct • Reviews use the commitment register and KPI actuals, not self-reports — CEO, monthly | E7: Cynthia Osakunih | F7: CO-KR6.2 | G7: 46296 | H7: 46371
A8: PC-KR1.2 | B8: From October, the company commitment register holds every function's CEO-approved monthly commitments with acceptance criteria and original dates, and the month-end delivery report reaches the CEO by the 3rd business day of each following month. | C8: Enabling → PC-K06 from Q1 | D8: • Register template and function-head briefing — 3 Oct • Month-end delivery report with missed items and recovery owners — monthly | E8: Cynthia Osakunih | F8: CO-KR6.1 | G8: 46296 | H8: 46387
A9: PC-KR1.3 | B9: The staff handbook and five priority policies (leave, hybrid work, incentives, recruitment, onboarding) are issued and acknowledged by 100% of employees by 31 October. | C9: Enabling | D9: • Final approval — CEO, 15 Oct • Briefings and written acknowledgement — 31 Oct | E9: Cynthia Osakunih | F9: CO-O6 (no company KR) | G9: 46296 | H9: 46326
A10: PC-O2 Digitise core HR and staff the critical roles. | L10: =IFERROR(ROUND(AVERAGE(L11:L13),2),"") | M10: =IFERROR(ROUND(AVERAGE(M11:M13),2),"") | N10: =IFERROR(ROUND(AVERAGE(N11:N13),2),"")
A11: PC-KR2.1 | B11: Leave, employee records and onboarding run end to end in a live HRIS by 31 December. Migrated records reconcile to the source files and the Excel files for those processes are retired. The remaining HR processes are inventoried, with owners and a Q1–Q2 2027 digitisation sequence. | C11: Enabling — first phase of HR digitisation | D11: • HR process inventory with owners, cycle times and risk ranking — 31 Oct • HRIS shortlist, demos and selection against the inventory and approved budget — 20 Nov • Configure leave, records and onboarding; migrate and reconcile employee records — 18 Dec • Role-based access check and staff training — 31 Dec | E11: Cynthia Osakunih | F11: CO-O6 (no company KR) | G11: 46296 | H11: 46387
A12: PC-KR2.2 | B12: The CEO approves the customer-support role design, staffing and training by 15 October, and support staff are hired or assigned by 10 November. | C12: Enabling | D12: • Role, coverage and cost options — 10 Oct • Hire or assign and train, with back-office Ops — 10 Nov | E12: Cynthia Osakunih | F12: CO-KR2.3 | G12: 46296 | H12: 46336
A13: PC-KR2.3 | B13: A Head of Partnership is hired, with a signed offer and a start date, by 31 October. | C13: Enabling | D13: • Role profile and Q4 scorecard approved — CEO, 5 Oct • Shortlist and interviews — CEO, 20 Oct • Offer signed — 31 Oct • Onboarding plan, including handover of the Ember2Remember calendar pipeline — from start date | E13: Cynthia Osakunih | F13: CO-O6 (no company KR) | G13: 46296 | H13: 46326
A15: Operational KPIs
A16: Recurring measures of how well the function runs, each with one formula, a target and a data source. No KPI repeats a KR. No eligible cases means N/A, not 100%. Overdue cases stay in the denominator. Record each month’s actual; KPIs are not scored.
A17: KPI ID | B17: KPI | C17: Formula | D17: Unit | E17: Direction | F17: Target | G17: Frequency | H17: Data source | I17: Result | J17: Actual | K17: Comment | L17: October | M17: November | N17: December
A18: PC-K01 | B18: Payroll input accuracy rate | C18: Payroll records accepted without a P&C-caused correction ÷ records submitted | D18: % | E18: Higher is better | F18: 100% | G18: Each payroll | H18: Payroll processor report
A19: PC-K02 | B19: On-time payroll submission rate | C19: Payroll submissions accepted before the processor deadline ÷ submissions due | D19: % | E19: Higher is better | F19: 100% | G19: Each payroll | H19: Payroll processor report
A20: PC-K03 | B20: HR request resolution rate | C20: Leave, record and payroll queries resolved within 2 business days ÷ requests due | D20: % | E20: Higher is better | F20: ≥90% | G20: Monthly | H20: HR request log (HRIS from go-live)
A21: PC-K04 | B21: Day-one onboarding readiness rate | C21: New joiners with manager, system access, equipment and briefing ready on day one ÷ joiners | D21: % | E21: Higher is better | F21: 100% | G21: Each intake | H21: Onboarding checklist
A22: PC-K05 | B22: Unauthorised HR-record access incidents | C22: Confirmed incidents of HR records viewed, shared or changed without authority | D22: Count | E22: Lower is better | F22: 0 | G22: Monthly | H22: Access log; incident reports
A23: PC-K06 | B23: On-time monthly function report rate | C23: Function reports (Target–Actual–Variance–Action) submitted by the 3rd business day ÷ reports due | D23: % | E23: Higher is better | F23: 100% | G23: Monthly | H23: Commitment register
A24: Baselines for every KPI come from CO-KR1.1 (31 October). Data sources are records available today; none depends on the analytics tool unless stated.

Sheet Changes vs Revised Draft
A1: What changed from the Sep–Dec revised draft, and why
A2: MyCityApp and MyLagosApp · Q4 2026 (Oct–Dec) · Foundation draft for review
A4: Area | B4: Revised draft | C4: This draft | D4: Reason
A5: Revenue | B5: ₦500m earned in Q4, with ₦200m having no delivery case | C5: Q4 revenue ₦200m earned Oct–Dec (10% of ₦2bn plan-year revenue): ₦163.3m allocated by stream (CO-KR5.1), ₦30m pending CEO allocation | D5: Q4 is phased at 10% of the year like every other target; the earlier December-month figure took 10% of a run rate
A6: Ticketing | B6: ₦75m revenue on ₦125m ticket value | C6: ₦30m ticketing revenue in Q4 (10% of ₦300m), at an average contracted rate of at least 12% on ₦250m ticket value (PG-KR2.3) | D6: A 60% take rate is not plausible
A7: Reservations | B7: Live in both apps by 31 Oct; revenue targets pending | C7: Hotel and shortlet booking, restaurant booking and in-restaurant payment live in both apps by 30 Nov (P0); 250 stays and 150 restaurant partners signed by 31 Dec (PG-KR1.2, PG-KR1.3) | D7: The feature has to exist before revenue can be targeted
A8: Baselines | B8: MAU, contacts and retention measured against August | C8: Verified baseline by 31 Oct; analytics by 15 Nov; activation and month-2 return | D8: August can't be rebuilt on actions that were never recorded
A9: Retention | B9: 60% at days 84–90 for the September cohort | C9: 7-day activation and month-2 return in Q4; the 60% standard from Q1 2027 | D9: No baseline, no tracking, and September activations can't be identified
A10: Cascade | B10: 13 function KRs copied word for word from company KRs | C10: Each function KR is that function's own lever, and contributions add up | D10: Nobody owned the parts; P&G and Marketing held company totals they couldn't control
A11: Retention ownership | B11: No owner; P&G counted sign-ups | C11: Marketing owns acquisition, activation and repeat use from every channel, with a named lifecycle lead. P&G is scored on supply, distribution placements and account revenue, not users | D11: Nobody made event sign-ups stay, and salespeople don't control what users do in the app
A12: Notifications | B12: Not addressed | C12: ≤3 promotional pushes per user per week; caps and preference centre in the app | D12: About 300 a day observed; users turn off notifications or uninstall
A13: Exclusivity | B13: Offer count pending | C13: 25 exclusive December events; an exclusive benefit in every partner's terms | D13: Customers need a reason to use the app rather than the alternatives
A14: Technology load | B14: 15 KRs; six releases on 31 Oct and three on 30 Nov; Flex migration during the payment month | C14: Technology & Back-office Ops holds 9 KRs on 3 objectives. All Q4 launches sit in one dated delivery KR (TBO-KR2.1) with a no-regression guard (TBO-KR2.2); Flex paused; December freeze | D14: The plan wasn't deliverable, and it put the December peak at risk
A15: KR/KPI duplicates | B15: Several KRs repeated as KPIs with the same targets | C15: No KPI repeats a KR | D15: Prevents crediting the same result twice
... A38: Reporting and scoring | B38: No reporting columns | C38: Status, Actual and Update per KR, kept current; a score per month (Oct, Nov, Dec); KPI monthly actuals; Q4 Scorecard roll-up | D38: Function heads report and score their own KRs
A40: Former ID → new ID
A41: Former ID | B41: New ID | C41: Note
A42: BM-KR1.2 | B42: BM-K15 | C42: Now a KPI
