Workbook

Sheet Staff Register
A1: Staff register and score summary
A3: Staff ID | B3: Name | C3: Designation | D3: Team | E3: OKR function | F3: Reviewer | G3: Scope | H3: Score to date | I3: Rating
A4: 00001 | B4: Ifeoma Mbonu | C4: Chief Executive Officer | D4: General Management | E4: Company | F4: Board (to be confirmed) | G4: Company strategy, reserved decisions, product ownership (interim) and accountability across all functions | H4: ='00001 Ifeoma Mbonu'!L26 | I4: ='00001 Ifeoma Mbonu'!L27
A5: 00002 | B5: Precious Iyersehen | C5: Graphics Designer | D5: Marketing | E5: Branding & Marketing | F5: Chinyere Elechi | G5: Creative production for all three apps | H5: ='00002 Precious Iyersehen'!L26 | I5: ='00002 Precious Iyersehen'!L27
A6: 00003 | B6: Oladotun Shola Adido | C6: Back-end Manager | D6: Operations - Lead | E6: Operations | F6: Ifeoma Mbonu | G6: Content listing in all three apps; customer support | H6: ='00003 Oladotun Shola Adido'!L28 | I6: ='00003 Oladotun Shola Adido'!L29
A7: 00005 | B7: Tobiloba Dada | C7: Content & Listing Associate | D7: Operations - MyCityApp - NG & MyLagosApp | E7: Operations | F7: Oladotun Shola Adido | G7: MyCityApp Nigeria and MyLagosApp content | H7: ='00005 Tobiloba Dada'!L26 | I7: ='00005 Tobiloba Dada'!L27
A8: 00006 | B8: Tochukwu Ifeanyi | C8: Marketing Lead - Abuja | D8: Marketing & Partnership | E8: Partnership & Growth | F8: Abubakar Mohammed (dotted line: Chinyere Elechi) | G8: Abuja market — FCT | H8: ='00006 Tochukwu Ifeanyi'!L27 | I8: ='00006 Tochukwu Ifeanyi'!L28
A9: 00009 | B9: Emmanuel Aneke | C9: Marketing & Growth Officer - Rivers | D9: Partnership & Growth | E9: Partnership & Growth | F9: Abubakar Mohammed | G9: South South — Rivers | H9: ='00009 Emmanuel Aneke'!L26 | I9: ='00009 Emmanuel Aneke'!L27
A10: 00010 | B10: Cynthia Osakunih | C10: Operations & People Lead | D10: HR & Operations | E10: People & Culture | F10: Ifeoma Mbonu | G10: Company-wide people processes, performance cycle and commitment register | H10: ='00010 Cynthia Osakunih'!L29 | I10: ='00010 Cynthia Osakunih'!L30
A11: 00011 | B11: John Ojelola | C11: Marketing Lead - South West | D11: Partnership & Growth | E11: Partnership & Growth | F11: Abubakar Mohammed | G11: South West — Ibadan and retained accounts | H11: ='00011 John Ojelola'!L26 | I11: ='00011 John Ojelola'!L27
A12: 00012 | B12: Bassey Ekpe | C12: Content & Listing Associate | D12: Operations (Botswana - MyCityApp - Africa) | E12: Operations | F12: Oladotun Shola Adido | G12: MyCityApp Africa — Botswana content | H12: ='00012 Bassey Ekpe'!L25 | I12: ='00012 Bassey Ekpe'!L26
A13: 00013 | B13: Aaron Agama | C13: Social Media Manager | D13: Marketing | E13: Branding & Marketing | F13: Chinyere Elechi | G13: Social channels and creators for all three apps; send calendar | H13: ='00013 Aaron Agama'!L29 | I13: ='00013 Aaron Agama'!L30
A14: 00014 | B14: Abubakar Mohammed | C14: Head Strategy, Partnerships & Growth | D14: Partnership & Growth | E14: Partnership & Growth | F14: Ifeoma Mbonu | G14: Function leadership; Lagos and national accounts; interim Kano cover | H14: ='00014 Abubakar Mohammed'!L31 | I14: ='00014 Abubakar Mohammed'!L32
A15: 00016 | B15: Bode Oluwasanmi | C15: Chief Technology Officer | D15: Technology | E15: Technology | F15: Ifeoma Mbonu | G15: All three apps; MTNN and other delivery vendors | H15: ='00016 Bode Oluwasanmi'!L30 | I15: ='00016 Bode Oluwasanmi'!L31
A16: 00017 | B16: Gideon Ekom | C16: Marketing & Growth Officer - Enugu | D16: Partnership & Growth | E16: Partnership & Growth | F16: Abubakar Mohammed | G16: South East — Enugu | H16: ='00017 Gideon Ekom'!L26 | I16: ='00017 Gideon Ekom'!L27
A17: 00018 | B17: Adaeze Chike | C17: Marketing & Growth Officer - Abia | D17: Partnership & Growth | E17: Partnership & Growth | F17: Abubakar Mohammed | G17: South East — Abia | H17: ='00018 Adaeze Chike'!L26 | I17: ='00018 Adaeze Chike'!L27
A18: 00019 | B18: Chinyere Elechi | C18: Head PR, Marketing & Brand Strategy | D18: Marketing - Lead | E18: Branding & Marketing | F18: Ifeoma Mbonu | G18: Function leadership; paid campaigns; brand; lifecycle (activation and repeat use) unless the CEO names another lead by 25 Sep | H18: ='00019 Chinyere Elechi'!L30 | I18: ='00019 Chinyere Elechi'!L31
A19: 00020 | B19: David Idowu-Agida | C19: PR & Marketing Lead - MyLagosApp | D19: Marketing | E19: Branding & Marketing | F19: Chinyere Elechi | G19: MyLagosApp / Lagos PR and campaigns | H19: ='00020 David Idowu-Agida'!L28 | I19: ='00020 David Idowu-Agida'!L29

Sheet 00001 Ifeoma Mbonu
A1: Q4 2026 scorecard — Ifeoma Mbonu
A3: Staff ID | B3: 00001
A4: Designation | B4: Chief Executive Officer
A5: Team | B5: General Management
A6: OKR function | B6: Company
A7: Reviewer | B7: Board (to be confirmed)
A8: Scope | B8: Company strategy, reserved decisions, product ownership (interim) and accountability across all functions
A9: Period | B9: 1 Oct – 31 Dec 2026
A11: # | B11: Section | C11: Goal / KPI | D11: Target and how it is measured | E11: Linked KR / KPI | F11: Due / frequency | G11: Weight | H11: Oct | I11: Nov | J11: Dec | K11: Score (0–1) | L11: Weighted
A12: Results — 60%
A13: 1 | B13: Result | C13: Make the Q4 decisions that unblock the plan | D13: All eleven decisions in the OKR workbook's Read Me recorded with owner and date by 10 Oct (lifecycle lead by 25 Sep; HRIS budget by 31 Oct) | E13: Read Me decisions 1–11 | F13: 10 Oct | G13: 10 | K13: =IF(J13<>"",J13,IF(I13<>"",I13,IF(H13<>"",H13,""))) | L13: =IF(K13="","",G13*K13)
A14: 2 | B14: Result | C14: Verified opening baseline signed off | D14: One baseline for downloads per app, active users, transactions, ticket value and revenue by stream, Jan–Sep, signed by 31 Oct; all [TBC] targets locked by 7 Nov | E14: CO-KR1.1 | F14: 31 Oct | G14: 10 | K14: =IF(J14<>"",J14,IF(I14<>"",I14,IF(H14<>"",H14,""))) | L14: =IF(K14="","",G14*K14)
A15: 3 | B15: Result | C15: Product roadmap approved | D15: One roadmap sequencing every Q4 2026–Q3 2027 feature, each with an MTNN month and acceptance owner, approved by 15 Oct | E15: CO-KR1.3 | F15: 15 Oct | G15: 10 | K15: =IF(J15<>"",J15,IF(I15<>"",I15,IF(H15<>"",H15,""))) | L15: =IF(K15="","",G15*K15)
A16: 4 | B16: Result | C16: December platform revenue | D16: ₦16.7m platform revenue earned in December (₦200m annualised run rate) | E16: CO-KR5.1 | F16: 31 Dec | G16: 15 | K16: =IF(J16<>"",J16,IF(I16<>"",I16,IF(H16<>"",H16,""))) | L16: =IF(K16="","",G16*K16)
A17: 5 | B17: Result | C17: Function commitments kept | D17: Each function delivers ≥80% of its CEO-approved monthly commitments by the original date, in November and in December | E17: CO-KR6.1 | F17: Nov; Dec | G17: 15 | K17: =IF(J17<>"",J17,IF(I17<>"",I17,IF(H17<>"",H17,""))) | L17: =IF(K17="","",G17*K17)
A18: KPIs — 25%
A19: 6 | B19: KPI | C19: Recovery-decision turnaround rate | D19: 100% — missed commitments in the month-end report with a recovery decision (owner, date) within 5 business days of the report. Source: commitment register | E19: CO-KR6.1 | F19: Monthly | G19: 10 | K19: =IF(COUNT(H19:J19)=0,"",AVERAGE(H19:J19)) | L19: =IF(K19="","",G19*K19)
A20: 7 | B20: KPI | C20: Company budget variance | D20: ≤0% — (actual + committed spend − approved budget) ÷ approved budget. Source: finance records | E20: — | F20: Monthly | G20: 15 | K20: =IF(COUNT(H20:J20)=0,"",AVERAGE(H20:J20)) | L20: =IF(K20="","",G20*K20)
A21: Accountability — 15%
A22: 8 | B22: Accountability | C22: On-time reserved-decision rate | D22: ≥90% of CEO-reserved decisions in the register made by the agreed date | E22: CO-KR6.1 | F22: Monthly | G22: 8 | K22: =IF(COUNT(H22:J22)=0,"",AVERAGE(H22:J22)) | L22: =IF(K22="","",G22*K22)
A23: 9 | B23: Accountability | C23: Function-head scorecards and reviews | D23: Five function-head scorecards signed by 25 Sep; October and November reviews completed by 15 Dec | E23: CO-KR6.2 | F23: 25 Sep; 15 Dec | G23: 7 | K23: =IF(COUNT(H23:J23)=0,"",AVERAGE(H23:J23)) | L23: =IF(K23="","",G23*K23)
J25: Total weight | L25: =SUM(G12:G23) -> 100
J26: Score to date | L26: =IFERROR(SUM(L12:L23)/SUMPRODUCT((K12:K23<>"")*G12:G23),"")
J27: Rating | L27: =IF(L26="","",IF(L26>=0.9,"Exceeds",IF(L26>=0.75,"Meets",IF(L26>=0.5,"Partly meets","Below"))))
A29: Agreement — to be signed by 25 September 2026 at the latest
C30: Employee: Ifeoma Mbonu Signature / date: ______________ | D30: Reviewer: Board Signature / date: ______________

Sheet 00002 Precious Iyersehen
A1: Q4 2026 scorecard — Precious Iyersehen
A3: Staff ID | B3: 00002
A4: Designation | B4: Graphics Designer
A5: Team | B5: Marketing
A6: OKR function | B6: Branding & Marketing
A7: Reviewer | B7: Chinyere Elechi
A8: Scope | B8: Creative production for all three apps
A9: Period | B9: 1 Oct – 31 Dec 2026
A11: # | B11: Section | C11: Goal / KPI | D11: Target and how it is measured | E11: Linked KR / KPI | F11: Due / frequency | G11: Weight | H11: Oct | I11: Nov | J11: Dec | K11: Score (0–1) | L11: Weighted
A12: Results — 60%
A13: 1 | B13: Result | C13: Team result — Marketing | D13: Average attainment of the two Marketing outcome KRs: 40,000 users activated from all channels (BM-KR1.3) and ₦20m paid-ticket value through marketing (BM-KR2.1). Same score for every Marketing team member; owned by Chinyere Elechi | E13: BM-KR1.3; BM-KR2.1 | F13: 31 Dec | G13: 10 | K13: =IF(J13<>"",J13,IF(I13<>"",I13,IF(H13<>"",H13,""))) | L13: =IF(K13="","",G13*K13)
A14: 2 | B14: Result | C14: Brand Book visual system | D14: Colour, type, logo use and naming lock-ups for the three apps, plus templates for store pages, social and campaigns, submitted for approval by 24 Oct | E14: BM-KR3.1 | F14: 24 Oct | G14: 20 | K14: =IF(J14<>"",J14,IF(I14<>"",I14,IF(H14<>"",H14,""))) | L14: =IF(K14="","",G14*K14)
A15: 3 | B15: Result | C15: Festive-season campaign kits | D15: Asset kits for December events, stays and LASG payments delivered by 10 Nov (Lagos) and 20 Nov (other markets) | E15: BM-KR2.1; BM-KR1.3 | F15: 10 Nov; 20 Nov | G15: 15 | K15: =IF(J15<>"",J15,IF(I15<>"",I15,IF(H15<>"",H15,""))) | L15: =IF(K15="","",G15*K15)
A16: 4 | B16: Result | C16: LASG payment guides | D16: One screen-based guide per enabled LASG bill type, ready by LASG go-live (15 Nov) | E16: TECH-KR2.1; BM-KR1.3 | F16: 15 Nov | G16: 15 | K16: =IF(J16<>"",J16,IF(I16<>"",I16,IF(H16<>"",H16,""))) | L16: =IF(K16="","",G16*K16)
A17: KPIs — 25%
A18: 5 | B18: KPI | C18: On-time creative asset delivery rate | D18: ≥95% — Campaign assets delivered by the agreed deadline ÷ assets due. Source: Creative request tracker | E18: BM-K03 | F18: Monthly | G18: 10 | K18: =IF(COUNT(H18:J18)=0,"",AVERAGE(H18:J18)) | L18: =IF(K18="","",G18*K18)
A19: 6 | B19: KPI | C19: Creative first-pass approval rate | D19: ≥85% — First submissions approved without substantial rework against the brief ÷ first submissions. Source: Creative request tracker | E19: BM-K04 | F19: Monthly | G19: 8 | K19: =IF(COUNT(H19:J19)=0,"",AVERAGE(H19:J19)) | L19: =IF(K19="","",G19*K19)
A20: 7 | B20: KPI | C20: Brand compliance rate — new assets | D20: 100% — New published assets passing Brand Book, price, date and claim checks ÷ new assets checked (all paid, sample of organic). Source: Brand review log | E20: BM-K09 | F20: Monthly from 1 Nov | G20: 7 | K20: =IF(COUNT(H20:J20)=0,"",AVERAGE(H20:J20)) | L20: =IF(K20="","",G20*K20)
A21: Accountability — 15%
A22: 8 | B22: Accountability | C22: On-time commitment delivery rate | D22: ≥80% of your agreed monthly commitments in the company register delivered by the original date | E22: CO-KR6.1 | F22: Monthly | G22: 10 | K22: =IF(COUNT(H22:J22)=0,"",AVERAGE(H22:J22)) | L22: =IF(K22="","",G22*K22)
A23: 9 | B23: Accountability | C23: Monthly update on time | D23: Target–Actual–Variance–Action update to your reviewer by the 2nd business day of each month | E23: PC-K06 | F23: Monthly | G23: 5 | K23: =IF(COUNT(H23:J23)=0,"",AVERAGE(H23:J23)) | L23: =IF(K23="","",G23*K23)
J25: Total weight | L25: =SUM(G12:G23) -> 100
J26: Score to date | L26: =IFERROR(SUM(L12:L23)/SUMPRODUCT((K12:K23<>"")*G12:G23),"")
J27: Rating | L27: =IF(L26="","",IF(L26>=0.9,"Exceeds",IF(L26>=0.75,"Meets",IF(L26>=0.5,"Partly meets","Below"))))
A29: Agreement — to be signed by 25 September 2026 at the latest
C30: Employee: Precious Iyersehen Signature / date: ______________ | D30: Reviewer: Chinyere Elechi Signature / date: ______________

Sheet 00003 Oladotun Shola Adido
A1: Q4 2026 scorecard — Oladotun Shola Adido
A3: Staff ID | B3: 00003
A4: Designation | B4: Back-end Manager
A5: Team | B5: Operations - Lead
A6: OKR function | B6: Operations
A7: Reviewer | B7: Ifeoma Mbonu
A8: Scope | B8: Content listing in all three apps; customer support
A9: Period | B9: 1 Oct – 31 Dec 2026
A11: # | B11: Section | C11: Goal / KPI | D11: Target and how it is measured | E11: Linked KR / KPI | F11: Due / frequency | G11: Weight | H11: Oct | I11: Nov | J11: Dec | K11: Score (0–1) | L11: Weighted
A12: Results — 60%
A13: 1 | B13: Result | C13: Customer support live and resolving | D13: Support live on published channels with a case log by 15 Nov; ≥85% of December cases resolved within 48 hours | E13: OP-KR3.1 | F13: 15 Nov; 31 Dec | G13: 20 | K13: =IF(J13<>"",J13,IF(I13<>"",I13,IF(H13<>"",H13,""))) | L13: =IF(K13="","",G13*K13)
A14: 2 | B14: Result | C14: Listing accuracy in every app | D14: ≥98% of audited live events, stays and business listings pass checks in December, in each of the three apps (October audit is the baseline) | E14: OP-KR1.2 | F14: 31 Dec | G14: 15 | K14: =IF(J14<>"",J14,IF(I14<>"",I14,IF(H14<>"",H14,""))) | L14: =IF(K14="","",G14*K14)
A15: 3 | B15: Result | C15: Supply live within two business days | D15: 95% of complete, approved submissions published within 2 business days in November and December | E15: OP-KR2.1 | F15: Nov; Dec | G15: 15 | K15: =IF(J15<>"",J15,IF(I15<>"",I15,IF(H15<>"",H15,""))) | L15: =IF(K15="","",G15*K15)
A16: 4 | B16: Result | C16: Business profiles published | D16: 5,000 new owner-verified MyCityApp Nigeria profiles with all required fields published in Q4 (team total) | E16: OP-KR2.2 | F16: 31 Dec | G16: 10 | K16: =IF(J16<>"",J16,IF(I16<>"",I16,IF(H16<>"",H16,""))) | L16: =IF(K16="","",G16*K16)
A17: KPIs — 25%
A18: 5 | B18: KPI | C18: Event expiry compliance rate | D18: ≥98% — One-off events removed from upcoming listings within 24 hours of their end time ÷ events due for removal. Source: Listing audit; admin log | E18: OP-K01 | F18: Monthly, per app | G18: 8 | K18: =IF(COUNT(H18:J18)=0,"",AVERAGE(H18:J18)) | L18: =IF(K18="","",G18*K18)
A19: 6 | B19: KPI | C19: Support first-response rate | D19: ≥90% — Cases receiving a first useful response within 4 business hours ÷ cases received. Source: Support case log | E19: OP-K06 | F19: Monthly from launch | G19: 7 | K19: =IF(COUNT(H19:J19)=0,"",AVERAGE(H19:J19)) | L19: =IF(K19="","",G19*K19)
A20: 7 | B20: KPI | C20: Listing correction turnaround rate | D20: ≥95% — Confirmed listing errors corrected or withdrawn within 1 business day ÷ errors due. Source: Correction log | E20: OP-K03 | F20: Monthly | G20: 5 | K20: =IF(COUNT(H20:J20)=0,"",AVERAGE(H20:J20)) | L20: =IF(K20="","",G20*K20)
A21: 8 | B21: KPI | C21: Unresolved critical contact errors | D21: 0 — Confirmed wrong hospital, police or fire-service entries not yet corrected or hidden. Source: Correction log | E21: OP-K04 | F21: Monthly maximum | G21: 5 | K21: =IF(COUNT(H21:J21)=0,"",AVERAGE(H21:J21)) | L21: =IF(K21="","",G21*K21)
A22: Accountability — 15%
A23: 9 | B23: Accountability | C23: On-time commitment delivery rate | D23: ≥80% of your CEO-approved monthly commitments in the company register delivered by the original date | E23: CO-KR6.1 | F23: Monthly | G23: 8 | K23: =IF(COUNT(H23:J23)=0,"",AVERAGE(H23:J23)) | L23: =IF(K23="","",G23*K23)
A24: 10 | B24: Accountability | C24: Monthly function report on time | D24: Target–Actual–Variance–Action report submitted by the 3rd business day of each month | E24: PC-K06 | F24: Monthly | G24: 3 | K24: =IF(COUNT(H24:J24)=0,"",AVERAGE(H24:J24)) | L24: =IF(K24="","",G24*K24)
A25: 11 | B25: Accountability | C25: Team scorecards and reviews | D25: Every direct report has a signed scorecard by 25 Sep; October and November reviews completed by 15 Dec | E25: PC-KR1.1; PC-KR1.2 | F25: 25 Sep; 15 Dec | G25: 4 | K25: =IF(COUNT(H25:J25)=0,"",AVERAGE(H25:J25)) | L25: =IF(K25="","",G25*K25)
J27: Total weight | L27: =SUM(G12:G25) -> 100
J28: Score to date | L28: =IFERROR(SUM(L12:L25)/SUMPRODUCT((K12:K25<>"")*G12:G25),"")
J29: Rating | L29: =IF(L28="","",IF(L28>=0.9,"Exceeds",IF(L28>=0.75,"Meets",IF(L28>=0.5,"Partly meets","Below"))))
A31: Agreement — to be signed by 25 September 2026 at the latest
C32: Employee: Oladotun Shola Adido Signature / date: ______________ | D32: Reviewer: Ifeoma Mbonu Signature / date: ______________

Sheet 00005 Tobiloba Dada
A1: Q4 2026 scorecard — Tobiloba Dada
A3: Staff ID | B3: 00005
A4: Designation | B4: Content & Listing Associate
A5: Team | B5: Operations - MyCityApp - NG & MyLagosApp
A6: OKR function | B6: Operations
A7: Reviewer | B7: Oladotun Shola Adido
A8: Scope | B8: MyCityApp Nigeria and MyLagosApp content
A9: Period | B9: 1 Oct – 31 Dec 2026
A11: # | B11: Section | C11: Goal / KPI | D11: Target and how it is measured | E11: Linked KR / KPI | F11: Due / frequency | G11: Weight | H11: Oct | I11: Nov | J11: Dec | K11: Score (0–1) | L11: Weighted
A12: Results — 60%
A13: 1 | B13: Result | C13: No stale events | D13: No expired one-off event shown as upcoming in MyLagosApp or MyCityApp Nigeria at any daily check from 30 Sep to 31 Dec | E13: OP-KR1.1 | F13: Daily to 31 Dec | G13: 15 | K13: =IF(J13<>"",J13,IF(I13<>"",I13,IF(H13<>"",H13,""))) | L13: =IF(K13="","",G13*K13)
A14: 2 | B14: Result | C14: Directly sourced business profiles | D14: 2,000 owner-verified Lagos business profiles sourced and published by you in Q4 (the other 3,000 come from Partnership & Growth submissions) | E14: OP-KR2.2 | F14: 31 Dec | G14: 15 | K14: =IF(J14<>"",J14,IF(I14<>"",I14,IF(H14<>"",H14,""))) | L14: =IF(K14="","",G14*K14)
A15: 3 | B15: Result | C15: Nigerian catalogue audit and corrections | D15: Audit and correction batches completed on the dates agreed with Oladotun; all hospital, police and fire-service contacts verified by 30 Nov | E15: OP-KR1.2 | F15: 30 Nov | G15: 15 | K15: =IF(J15<>"",J15,IF(I15<>"",I15,IF(H15<>"",H15,""))) | L15: =IF(K15="","",G15*K15)
A16: 4 | B16: Result | C16: December peak publishing | D16: Festive-season events and stays published within 1 business day of complete submission, 1–31 Dec | E16: OP-KR2.1 | F16: December | G16: 15 | K16: =IF(J16<>"",J16,IF(I16<>"",I16,IF(H16<>"",H16,""))) | L16: =IF(K16="","",G16*K16)
A17: KPIs — 25%
A18: 5 | B18: KPI | C18: Event expiry compliance rate | D18: ≥98% — One-off events removed from upcoming listings within 24 hours of their end time ÷ events due for removal. Source: Listing audit; admin log | E18: OP-K01 | F18: Monthly, per app | G18: 8 | K18: =IF(COUNT(H18:J18)=0,"",AVERAGE(H18:J18)) | L18: =IF(K18="","",G18*K18)
A19: 6 | B19: KPI | C19: Listing correction turnaround rate | D19: ≥95% — Confirmed listing errors corrected or withdrawn within 1 business day ÷ errors due. Source: Correction log | E19: OP-K03 | F19: Monthly | G19: 7 | K19: =IF(COUNT(H19:J19)=0,"",AVERAGE(H19:J19)) | L19: =IF(K19="","",G19*K19)
A20: 7 | B20: KPI | C20: Business profile completeness rate | D20: ≥95% — Published profiles with all required location, category, service and contact fields ÷ profiles audited. Source: Listing audit | E20: OP-K05 | F20: Monthly | G20: 10 | K20: =IF(COUNT(H20:J20)=0,"",AVERAGE(H20:J20)) | L20: =IF(K20="","",G20*K20)
A21: Accountability — 15%
A22: 8 | B22: Accountability | C22: On-time commitment delivery rate | D22: ≥80% of your agreed monthly commitments in the company register delivered by the original date | E22: CO-KR6.1 | F22: Monthly | G22: 10 | K22: =IF(COUNT(H22:J22)=0,"",AVERAGE(H22:J22)) | L22: =IF(K22="","",G22*K22)
A23: 9 | B23: Accountability | C23: Monthly update on time | D23: Target–Actual–Variance–Action update to your reviewer by the 2nd business day of each month | E23: PC-K06 | F23: Monthly | G23: 5 | K23: =IF(COUNT(H23:J23)=0,"",AVERAGE(H23:J23)) | L23: =IF(K23="","",G23*K23)
J25: Total weight | L25: =SUM(G12:G23) -> 100
J26: Score to date | L26: =IFERROR(SUM(L12:L23)/SUMPRODUCT((K12:K23<>"")*G12:G23),"")
J27: Rating | L27: =IF(L26="","",IF(L26>=0.9,"Exceeds",IF(L26>=0.75,"Meets",IF(L26>=0.5,"Partly meets","Below"))))
A29: Agreement — to be signed by 25 September 2026 at the latest
C30: Employee: Tobiloba Dada Signature / date: ______________ | D30: Reviewer: Oladotun Shola Adido Signature / date: ______________

Sheet 00006 Tochukwu Ifeanyi
A1: Q4 2026 scorecard — Tochukwu Ifeanyi
A3: Staff ID | B3: 00006
A4: Designation | B4: Marketing Lead - Abuja
A5: Team | B5: Marketing & Partnership
A6: OKR function | B6: Partnership & Growth
A7: Reviewer | B7: Abubakar Mohammed (dotted line: Chinyere Elechi)
A8: Scope | B8: Abuja market — FCT
A9: Period | B9: 1 Oct – 31 Dec 2026
A11: # | B11: Section | C11: Goal / KPI | D11: Target and how it is measured | E11: Linked KR / KPI | F11: Due / frequency | G11: Weight | H11: Oct | I11: Nov | J11: Dec | K11: Score (0–1) | L11: Weighted
A12: Results — 60%
A13: 1 | B13: Result | C13: Abuja ticketed events | D13: 30 ticketed Abuja events live in Q4 under signed commission terms, 4 of them December events on app-exclusive terms | E13: PG-KR1.1 | F13: 31 Dec | G13: 12 | K13: =IF(J13<>"",J13,IF(I13<>"",I13,IF(H13<>"",H13,""))) | L13: =IF(K13="","",G13*K13)
A14: 2 | B14: Result | C14: Abuja partners for the Q1 launch | D14: 60 restaurants and 50 hotels/shortlets in Abuja with signed terms (inventory, confirmation duty, fee, exclusive benefit) by 31 Dec | E14: PG-KR1.3 | F14: 31 Dec | G14: 18 | K14: =IF(J14<>"",J14,IF(I14<>"",I14,IF(H14<>"",H14,""))) | L14: =IF(K14="","",G14*K14)
A15: 3 | B15: Result | C15: Ticketing commission — Abuja accounts | D15: ₦750,000 [TBC] ticketing commission earned in Q4 from events you signed, at the contracted rate net of refunds (account owner on the pipeline record) | E15: PG-KR2.3 | F15: 31 Dec | G15: 10 | K15: =IF(J15<>"",J15,IF(I15<>"",I15,IF(H15<>"",H15,""))) | L15: =IF(K15="","",G15*K15)
A16: 4 | B16: Result | C16: Distribution placements — Abuja | D16: 6 live placements secured in Abuja (hotel guest messages, event ticket emails, association and conference channels), each with an agreed audience and a tracked link, handed to Marketing within 2 business days | E16: PG-KR3.1 | F16: 31 Dec | G16: 10 | K16: =IF(J16<>"",J16,IF(I16<>"",I16,IF(H16<>"",H16,""))) | L16: =IF(K16="","",G16*K16)
A17: 5 | B17: Result | C17: Abuja business submissions | D17: 700 owner-confirmed Abuja business submissions accepted by Operations in Q4 | E17: OP-KR2.2 | F17: 31 Dec | G17: 10 | K17: =IF(J17<>"",J17,IF(I17<>"",I17,IF(H17<>"",H17,""))) | L17: =IF(K17="","",G17*K17)
A18: KPIs — 25%
A19: 6 | B19: KPI | C19: On-time partner launch rate | D19: ≥90% — Signed partners and events live on the agreed date ÷ launches due (overdue launches stay in). Source: Pipeline register; publishing queue | E19: PG-K02 | F19: Monthly | G19: 10 | K19: =IF(COUNT(H19:J19)=0,"",AVERAGE(H19:J19)) | L19: =IF(K19="","",G19*K19)
A20: 7 | B20: KPI | C20: Signed-deal handover rate | D20: ≥95% — Signed deals accepted by the delivering team within 2 business days of signature ÷ deals signed. Source: Handover log | E20: PG-K03 | F20: Monthly | G20: 8 | K20: =IF(COUNT(H20:J20)=0,"",AVERAGE(H20:J20)) | L20: =IF(K20="","",G20*K20)
A21: 8 | B21: KPI | C21: Overdue sales follow-ups | D21: 0 — Qualified opportunities whose agreed next action is more than 5 business days overdue. Source: Pipeline register | E21: PG-K08 | F21: Weekly; monthly maximum | G21: 7 | K21: =IF(COUNT(H21:J21)=0,"",AVERAGE(H21:J21)) | L21: =IF(K21="","",G21*K21)
A22: Accountability — 15%
A23: 9 | B23: Accountability | C23: On-time commitment delivery rate | D23: ≥80% of your agreed monthly commitments in the company register delivered by the original date | E23: CO-KR6.1 | F23: Monthly | G23: 10 | K23: =IF(COUNT(H23:J23)=0,"",AVERAGE(H23:J23)) | L23: =IF(K23="","",G23*K23)
A24: 10 | B24: Accountability | C24: Monthly update on time | D24: Target–Actual–Variance–Action update to your reviewer by the 2nd business day of each month | E24: PC-K06 | F24: Monthly | G24: 5 | K24: =IF(COUNT(H24:J24)=0,"",AVERAGE(H24:J24)) | L24: =IF(K24="","",G24*K24)
J26: Total weight | L26: =SUM(G12:G24) -> 100
J27: Score to date | L27: =IFERROR(SUM(L12:L24)/SUMPRODUCT((K12:K24<>"")*G12:G24),"")
J28: Rating | L28: =IF(L27="","",IF(L27>=0.9,"Exceeds",IF(L27>=0.75,"Meets",IF(L27>=0.5,"Partly meets","Below"))))
A30: Agreement — to be signed by 25 September 2026 at the latest
C31: Employee: Tochukwu Ifeanyi Signature / date: ______________ | D31: Reviewer: Abubakar Mohammed Signature / date: ______________

Sheet 00009 Emmanuel Aneke
A1: Q4 2026 scorecard — Emmanuel Aneke
A3: Staff ID | B3: 00009
A4: Designation | B4: Marketing & Growth Officer - Rivers
A5: Team | B5: Partnership & Growth
A6: OKR function | B6: Partnership & Growth
A7: Reviewer | B7: Abubakar Mohammed
A8: Scope | B8: South South — Rivers
A9: Period | B9: 1 Oct – 31 Dec 2026
A11: # | B11: Section | C11: Goal / KPI | D11: Target and how it is measured | E11: Linked KR / KPI | F11: Due / frequency | G11: Weight | H11: Oct | I11: Nov | J11: Dec | K11: Score (0–1) | L11: Weighted
A12: Results — 60%
A13: 1 | B13: Result | C13: Rivers ticketed events | D13: 15 ticketed Rivers events live in Q4 under signed commission terms, 1 of them a December event on app-exclusive terms | E13: PG-KR1.1 | F13: 31 Dec | G13: 15 | K13: =IF(J13<>"",J13,IF(I13<>"",I13,IF(H13<>"",H13,""))) | L13: =IF(K13="","",G13*K13)
A14: 2 | B14: Result | C14: Ticketing commission — Rivers accounts | D14: ₦375,000 [TBC] ticketing commission earned in Q4 from events you signed, at the contracted rate net of refunds (account owner on the pipeline record) | E14: PG-KR2.3 | F14: 31 Dec | G14: 15 | K14: =IF(J14<>"",J14,IF(I14<>"",I14,IF(H14<>"",H14,""))) | L14: =IF(K14="","",G14*K14)
A15: 3 | B15: Result | C15: Distribution placements — Rivers | D15: 3 live placements secured in Rivers (hotel guest messages, event ticket emails, association channels), each with an agreed audience and a tracked link, handed to Marketing within 2 business days | E15: PG-KR3.1 | F15: 31 Dec | G15: 15 | K15: =IF(J15<>"",J15,IF(I15<>"",I15,IF(H15<>"",H15,""))) | L15: =IF(K15="","",G15*K15)
A16: 4 | B16: Result | C16: Rivers business submissions | D16: 600 owner-confirmed Rivers business submissions accepted by Operations in Q4 | E16: OP-KR2.2 | F16: 31 Dec | G16: 15 | K16: =IF(J16<>"",J16,IF(I16<>"",I16,IF(H16<>"",H16,""))) | L16: =IF(K16="","",G16*K16)
A17: KPIs — 25%
A18: 5 | B18: KPI | C18: On-time partner launch rate | D18: ≥90% — Signed partners and events live on the agreed date ÷ launches due (overdue launches stay in). Source: Pipeline register; publishing queue | E18: PG-K02 | F18: Monthly | G18: 10 | K18: =IF(COUNT(H18:J18)=0,"",AVERAGE(H18:J18)) | L18: =IF(K18="","",G18*K18)
A19: 6 | B19: KPI | C19: Signed-deal handover rate | D19: ≥95% — Signed deals accepted by the delivering team within 2 business days of signature ÷ deals signed. Source: Handover log | E19: PG-K03 | F19: Monthly | G19: 8 | K19: =IF(COUNT(H19:J19)=0,"",AVERAGE(H19:J19)) | L19: =IF(K19="","",G19*K19)
A20: 7 | B20: KPI | C20: Overdue sales follow-ups | D20: 0 — Qualified opportunities whose agreed next action is more than 5 business days overdue. Source: Pipeline register | E20: PG-K08 | F20: Weekly; monthly maximum | G20: 7 | K20: =IF(COUNT(H20:J20)=0,"",AVERAGE(H20:J20)) | L20: =IF(K20="","",G20*K20)
A21: Accountability — 15%
A22: 8 | B22: Accountability | C22: On-time commitment delivery rate | D22: ≥80% of your agreed monthly commitments in the company register delivered by the original date | E22: CO-KR6.1 | F22: Monthly | G22: 10 | K22: =IF(COUNT(H22:J22)=0,"",AVERAGE(H22:J22)) | L22: =IF(K22="","",G22*K22)
A23: 9 | B23: Accountability | C23: Monthly update on time | D23: Target–Actual–Variance–Action update to your reviewer by the 2nd business day of each month | E23: PC-K06 | F23: Monthly | G23: 5 | K23: =IF(COUNT(H23:J23)=0,"",AVERAGE(H23:J23)) | L23: =IF(K23="","",G23*K23)
J25: Total weight | L25: =SUM(G12:G23) -> 100
J26: Score to date | L26: =IFERROR(SUM(L12:L23)/SUMPRODUCT((K12:K23<>"")*G12:G23),"")
J27: Rating | L27: =IF(L26="","",IF(L26>=0.9,"Exceeds",IF(L26>=0.75,"Meets",IF(L26>=0.5,"Partly meets","Below"))))
A29: Agreement — to be signed by 25 September 2026 at the latest
C30: Employee: Emmanuel Aneke Signature / date: ______________ | D30: Reviewer: Abubakar Mohammed Signature / date: ______________

Sheet 00010 Cynthia Osakunih
A1: Q4 2026 scorecard — Cynthia Osakunih
A3: Staff ID | B3: 00010
A4: Designation | B4: Operations & People Lead
A5: Team | B5: HR & Operations
A6: OKR function | B6: People & Culture
A7: Reviewer | B7: Ifeoma Mbonu
A8: Scope | B8: Company-wide people processes, performance cycle and commitment register
A9: Period | B9: 1 Oct – 31 Dec 2026
A11: # | B11: Section | C11: Goal / KPI | D11: Target and how it is measured | E11: Linked KR / KPI | F11: Due / frequency | G11: Weight | H11: Oct | I11: Nov | J11: Dec | K11: Score (0–1) | L11: Weighted
A12: Results — 60%
A13: 1 | B13: Result | C13: Signed scorecards | D13: Every employee has a signed Q4 scorecard with their reviewer by 25 Sep | E13: PC-KR1.1 | F13: 25 Sep | G13: 10 | K13: =IF(J13<>"",J13,IF(I13<>"",I13,IF(H13<>"",H13,""))) | L13: =IF(K13="","",G13*K13)
A14: 2 | B14: Result | C14: Evidence-based reviews | D14: October and November reviews completed for 100% of eligible employees by 15 Dec, scored from actual results | E14: PC-KR1.2 | F14: 15 Dec | G14: 10 | K14: =IF(J14<>"",J14,IF(I14<>"",I14,IF(H14<>"",H14,""))) | L14: =IF(K14="","",G14*K14)
A15: 3 | B15: Result | C15: Handbook and priority policies | D15: Handbook and five priority policies issued and acknowledged by 100% of employees by 31 Oct | E15: PC-KR1.3 | F15: 31 Oct | G15: 10 | K15: =IF(J15<>"",J15,IF(I15<>"",I15,IF(H15<>"",H15,""))) | L15: =IF(K15="","",G15*K15)
A16: 4 | B16: Result | C16: Company commitment register | D16: Register live from October; month-end delivery report to the CEO by the 3rd business day in Nov, Dec and Jan | E16: PC-KR1.4 | F16: Monthly | G16: 10 | K16: =IF(J16<>"",J16,IF(I16<>"",I16,IF(H16<>"",H16,""))) | L16: =IF(K16="","",G16*K16)
A17: 5 | B17: Result | C17: HR digitisation, phase 1 | D17: Leave, employee records and onboarding live in an HRIS by 31 Dec; migrated records reconcile; Excel files for those processes retired | E17: PC-KR2.1 | F17: 31 Dec | G17: 12 | K17: =IF(J17<>"",J17,IF(I17<>"",I17,IF(H17<>"",H17,""))) | L17: =IF(K17="","",G17*K17)
A18: 6 | B18: Result | C18: Customer support staffed | D18: Support role design approved by 15 Oct; staff hired or assigned and trained by 10 Nov | E18: PC-KR2.2 | F18: 10 Nov | G18: 8 | K18: =IF(J18<>"",J18,IF(I18<>"",I18,IF(H18<>"",H18,""))) | L18: =IF(K18="","",G18*K18)
A19: KPIs — 25%
A20: 7 | B20: KPI | C20: Payroll input accuracy rate | D20: 100% — Payroll records accepted without a P&C-caused correction ÷ records submitted. Source: Payroll processor report | E20: PC-K01 | F20: Each payroll | G20: 7 | K20: =IF(COUNT(H20:J20)=0,"",AVERAGE(H20:J20)) | L20: =IF(K20="","",G20*K20)
A21: 8 | B21: KPI | C21: On-time payroll submission rate | D21: 100% — Payroll submissions accepted before the processor deadline ÷ submissions due. Source: Payroll processor report | E21: PC-K02 | F21: Each payroll | G21: 6 | K21: =IF(COUNT(H21:J21)=0,"",AVERAGE(H21:J21)) | L21: =IF(K21="","",G21*K21)
A22: 9 | B22: KPI | C22: HR request resolution rate | D22: ≥90% — Leave, record and payroll queries resolved within 2 business days ÷ requests due. Source: HR request log (HRIS from go-live) | E22: PC-K03 | F22: Monthly | G22: 6 | K22: =IF(COUNT(H22:J22)=0,"",AVERAGE(H22:J22)) | L22: =IF(K22="","",G22*K22)
A23: 10 | B23: KPI | C23: Unauthorised HR-record access incidents | D23: 0 — Confirmed incidents of HR records viewed, shared or changed without authority. Source: Access log; incident reports | E23: PC-K05 | F23: Monthly | G23: 6 | K23: =IF(COUNT(H23:J23)=0,"",AVERAGE(H23:J23)) | L23: =IF(K23="","",G23*K23)
A24: Accountability — 15%
A25: 11 | B25: Accountability | C25: On-time commitment delivery rate | D25: ≥80% of your agreed monthly commitments in the company register delivered by the original date | E25: CO-KR6.1 | F25: Monthly | G25: 10 | K25: =IF(COUNT(H25:J25)=0,"",AVERAGE(H25:J25)) | L25: =IF(K25="","",G25*K25)
A26: 12 | B26: Accountability | C26: Monthly update on time | D26: Target–Actual–Variance–Action update to your reviewer by the 2nd business day of each month | E26: PC-K06 | F26: Monthly | G26: 5 | K26: =IF(COUNT(H26:J26)=0,"",AVERAGE(H26:J26)) | L26: =IF(K26="","",G26*K26)
J28: Total weight | L28: =SUM(G12:G26) -> 100
J29: Score to date | L29: =IFERROR(SUM(L12:L26)/SUMPRODUCT((K12:K26<>"")*G12:G26),"")
J30: Rating | L30: =IF(L29="","",IF(L29>=0.9,"Exceeds",IF(L29>=0.75,"Meets",IF(L29>=0.5,"Partly meets","Below"))))
A32: Agreement — to be signed by 25 September 2026 at the latest
C33: Employee: Cynthia Osakunih Signature / date: ______________ | D33: Reviewer: Ifeoma Mbonu Signature / date: ______________

Sheet 00011 John Ojelola
A1: Q4 2026 scorecard — John Ojelola
A3: Staff ID | B3: 00011
A4: Designation | B4: Marketing Lead - South West
A5: Team | B5: Partnership & Growth
A6: OKR function | B6: Partnership & Growth
A7: Reviewer | B7: Abubakar Mohammed
A8: Scope | B8: South West — Ibadan and retained accounts
A9: Period | B9: 1 Oct – 31 Dec 2026
A11: # | B11: Section | C11: Goal / KPI | D11: Target and how it is measured | E11: Linked KR / KPI | F11: Due / frequency | G11: Weight | H11: Oct | I11: Nov | J11: Dec | K11: Score (0–1) | L11: Weighted
A12: Results — 60%
A13: 1 | B13: Result | C13: South West ticketed events | D13: 25 ticketed South West events live in Q4 under signed commission terms, 1 of them a December event on app-exclusive terms | E13: PG-KR1.1 | F13: 31 Dec | G13: 15 | K13: =IF(J13<>"",J13,IF(I13<>"",I13,IF(H13<>"",H13,""))) | L13: =IF(K13="","",G13*K13)
A14: 2 | B14: Result | C14: Ticketing commission — South West accounts | D14: ₦625,000 [TBC] ticketing commission earned in Q4 from events you signed, at the contracted rate net of refunds (account owner on the pipeline record) | E14: PG-KR2.3 | F14: 31 Dec | G14: 15 | K14: =IF(J14<>"",J14,IF(I14<>"",I14,IF(H14<>"",H14,""))) | L14: =IF(K14="","",G14*K14)
A15: 3 | B15: Result | C15: Distribution placements — South West | D15: 4 live placements secured in South West (hotel guest messages, event ticket emails, association channels), each with an agreed audience and a tracked link, handed to Marketing within 2 business days | E15: PG-KR3.1 | F15: 31 Dec | G15: 15 | K15: =IF(J15<>"",J15,IF(I15<>"",I15,IF(H15<>"",H15,""))) | L15: =IF(K15="","",G15*K15)
A16: 4 | B16: Result | C16: South West business submissions | D16: 700 owner-confirmed South West business submissions accepted by Operations in Q4 | E16: OP-KR2.2 | F16: 31 Dec | G16: 15 | K16: =IF(J16<>"",J16,IF(I16<>"",I16,IF(H16<>"",H16,""))) | L16: =IF(K16="","",G16*K16)
A17: KPIs — 25%
A18: 5 | B18: KPI | C18: On-time partner launch rate | D18: ≥90% — Signed partners and events live on the agreed date ÷ launches due (overdue launches stay in). Source: Pipeline register; publishing queue | E18: PG-K02 | F18: Monthly | G18: 10 | K18: =IF(COUNT(H18:J18)=0,"",AVERAGE(H18:J18)) | L18: =IF(K18="","",G18*K18)
A19: 6 | B19: KPI | C19: Signed-deal handover rate | D19: ≥95% — Signed deals accepted by the delivering team within 2 business days of signature ÷ deals signed. Source: Handover log | E19: PG-K03 | F19: Monthly | G19: 8 | K19: =IF(COUNT(H19:J19)=0,"",AVERAGE(H19:J19)) | L19: =IF(K19="","",G19*K19)
A20: 7 | B20: KPI | C20: Overdue sales follow-ups | D20: 0 — Qualified opportunities whose agreed next action is more than 5 business days overdue. Source: Pipeline register | E20: PG-K08 | F20: Weekly; monthly maximum | G20: 7 | K20: =IF(COUNT(H20:J20)=0,"",AVERAGE(H20:J20)) | L20: =IF(K20="","",G20*K20)
A21: Accountability — 15%
A22: 8 | B22: Accountability | C22: On-time commitment delivery rate | D22: ≥80% of your agreed monthly commitments in the company register delivered by the original date | E22: CO-KR6.1 | F22: Monthly | G22: 10 | K22: =IF(COUNT(H22:J22)=0,"",AVERAGE(H22:J22)) | L22: =IF(K22="","",G22*K22)
A23: 9 | B23: Accountability | C23: Monthly update on time | D23: Target–Actual–Variance–Action update to your reviewer by the 2nd business day of each month | E23: PC-K06 | F23: Monthly | G23: 5 | K23: =IF(COUNT(H23:J23)=0,"",AVERAGE(H23:J23)) | L23: =IF(K23="","",G23*K23)
J25: Total weight | L25: =SUM(G12:G23) -> 100
J26: Score to date | L26: =IFERROR(SUM(L12:L23)/SUMPRODUCT((K12:K23<>"")*G12:G23),"")
J27: Rating | L27: =IF(L26="","",IF(L26>=0.9,"Exceeds",IF(L26>=0.75,"Meets",IF(L26>=0.5,"Partly meets","Below"))))
A29: Agreement — to be signed by 25 September 2026 at the latest
C30: Employee: John Ojelola Signature / date: ______________ | D30: Reviewer: Abubakar Mohammed Signature / date: ______________

Sheet 00012 Bassey Ekpe
A1: Q4 2026 scorecard — Bassey Ekpe
A3: Staff ID | B3: 00012
A4: Designation | B4: Content & Listing Associate
A5: Team | B5: Operations (Botswana - MyCityApp - Africa)
A6: OKR function | B6: Operations
A7: Reviewer | B7: Oladotun Shola Adido
A8: Scope | B8: MyCityApp Africa — Botswana content
A9: Period | B9: 1 Oct – 31 Dec 2026
A11: # | B11: Section | C11: Goal / KPI | D11: Target and how it is measured | E11: Linked KR / KPI | F11: Due / frequency | G11: Weight | H11: Oct | I11: Nov | J11: Dec | K11: Score (0–1) | L11: Weighted
A12: Results — 60%
A13: 1 | B13: Result | C13: No stale events — MyCityApp Africa | D13: No expired one-off event shown as upcoming in MyCityApp Africa at any daily check from 30 Sep to 31 Dec | E13: OP-KR1.1 | F13: Daily to 31 Dec | G13: 20 | K13: =IF(J13<>"",J13,IF(I13<>"",I13,IF(H13<>"",H13,""))) | L13: =IF(K13="","",G13*K13)
A14: 2 | B14: Result | C14: Listing accuracy — MyCityApp Africa | D14: ≥98% of audited MyCityApp Africa listings pass date, price, location and contact checks in December (October audit is the baseline) | E14: OP-KR1.2 | F14: 31 Dec | G14: 20 | K14: =IF(J14<>"",J14,IF(I14<>"",I14,IF(H14<>"",H14,""))) | L14: =IF(K14="","",G14*K14)
A15: 3 | B15: Result | C15: Top listings refreshed | D15: The 300 most-viewed Botswana business listings re-verified with the business by 30 Nov | E15: OP-KR1.2 | F15: 30 Nov | G15: 20 | K15: =IF(J15<>"",J15,IF(I15<>"",I15,IF(H15<>"",H15,""))) | L15: =IF(K15="","",G15*K15)
A16: KPIs — 25%
A17: 4 | B17: KPI | C17: Event expiry compliance rate | D17: ≥98% — One-off events removed from upcoming listings within 24 hours of their end time ÷ events due for removal. Source: Listing audit; admin log | E17: OP-K01 | F17: Monthly, per app | G17: 8 | K17: =IF(COUNT(H17:J17)=0,"",AVERAGE(H17:J17)) | L17: =IF(K17="","",G17*K17)
A18: 5 | B18: KPI | C18: Listing correction turnaround rate | D18: ≥95% — Confirmed listing errors corrected or withdrawn within 1 business day ÷ errors due. Source: Correction log | E18: OP-K03 | F18: Monthly | G18: 7 | K18: =IF(COUNT(H18:J18)=0,"",AVERAGE(H18:J18)) | L18: =IF(K18="","",G18*K18)
A19: 6 | B19: KPI | C19: Business profile completeness rate | D19: ≥95% — Published profiles with all required location, category, service and contact fields ÷ profiles audited. Source: Listing audit | E19: OP-K05 | F19: Monthly | G19: 10 | K19: =IF(COUNT(H19:J19)=0,"",AVERAGE(H19:J19)) | L19: =IF(K19="","",G19*K19)
A20: Accountability — 15%
A21: 7 | B21: Accountability | C21: On-time commitment delivery rate | D21: ≥80% of your agreed monthly commitments in the company register delivered by the original date | E21: CO-KR6.1 | F21: Monthly | G21: 10 | K21: =IF(COUNT(H21:J21)=0,"",AVERAGE(H21:J21)) | L21: =IF(K21="","",G21*K21)
A22: 8 | B22: Accountability | C22: Monthly update on time | D22: Target–Actual–Variance–Action update to your reviewer by the 2nd business day of each month | E22: PC-K06 | F22: Monthly | G22: 5 | K22: =IF(COUNT(H22:J22)=0,"",AVERAGE(H22:J22)) | L22: =IF(K22="","",G22*K22)
J24: Total weight | L24: =SUM(G12:G22) -> 100
J25: Score to date | L25: =IFERROR(SUM(L12:L22)/SUMPRODUCT((K12:K22<>"")*G12:G22),"")
J26: Rating | L26: =IF(L25="","",IF(L25>=0.9,"Exceeds",IF(L25>=0.75,"Meets",IF(L25>=0.5,"Partly meets","Below"))))
A28: Agreement — to be signed by 25 September 2026 at the latest
C29: Employee: Bassey Ekpe Signature / date: ______________ | D29: Reviewer: Oladotun Shola Adido Signature / date: ______________

Sheet 00013 Aaron Agama
A1: Q4 2026 scorecard — Aaron Agama
A3: Staff ID | B3: 00013
A4: Designation | B4: Social Media Manager
A5: Team | B5: Marketing
A6: OKR function | B6: Branding & Marketing
A7: Reviewer | B7: Chinyere Elechi
A8: Scope | B8: Social channels and creators for all three apps; send calendar
A9: Period | B9: 1 Oct – 31 Dec 2026
A11: # | B11: Section | C11: Goal / KPI | D11: Target and how it is measured | E11: Linked KR / KPI | F11: Due / frequency | G11: Weight | H11: Oct | I11: Nov | J11: Dec | K11: Score (0–1) | L11: Weighted
A12: Results — 60%
A13: 1 | B13: Result | C13: Team result — Marketing | D13: Average attainment of the two Marketing outcome KRs: 40,000 users activated from all channels (BM-KR1.3) and ₦20m paid-ticket value through marketing (BM-KR2.1). Same score for every Marketing team member; owned by Chinyere Elechi | E13: BM-KR1.3; BM-KR2.1 | F13: 31 Dec | G13: 10 | K13: =IF(J13<>"",J13,IF(I13<>"",I13,IF(H13<>"",H13,""))) | L13: =IF(K13="","",G13*K13)
A14: 2 | B14: Result | C14: Festive-season social coverage | D14: Each of the 25 December exclusive events and each live stays partner gets at least 2 published posts and 1 creator piece, each with a tracked link to the in-app item, before the event or stay date | E14: BM-KR2.1; PG-KR1.1 | F14: Before each event; 31 Dec | G14: 15 | K14: =IF(J14<>"",J14,IF(I14<>"",I14,IF(H14<>"",H14,""))) | L14: =IF(K14="","",G14*K14)
A15: 3 | B15: Result | C15: Creator programme | D15: 10 creator collaborations published to brief in Q4 (disclosed as paid where paid), each with a tracked link to an in-app event, stay or service | E15: BM-KR1.3; BM-KR2.1 | F15: 20 Dec | G15: 10 | K15: =IF(J15<>"",J15,IF(I15<>"",I15,IF(H15<>"",H15,""))) | L15: =IF(K15="","",G15*K15)
A16: 4 | B16: Result | C16: Send calendar within the cap | D16: From 1 Nov, every promotional push is on the approved send calendar and no user exceeds 3 a week | E16: BM-KR1.2 | F16: Nov; Dec | G16: 10 | K16: =IF(J16<>"",J16,IF(I16<>"",I16,IF(H16<>"",H16,""))) | L16: =IF(K16="","",G16*K16)
A17: 5 | B17: Result | C17: Brand Book applied — MyCityApp Nigeria and Africa | D17: MyCityApp Nigeria and Africa social profiles and store pages conform to the Brand Book by 15 Dec | E17: BM-KR3.1 | F17: 15 Dec | G17: 15 | K17: =IF(J17<>"",J17,IF(I17<>"",I17,IF(H17<>"",H17,""))) | L17: =IF(K17="","",G17*K17)
A18: KPIs — 25%
A19: 6 | B19: KPI | C19: Content calendar coverage | D19: ≥28 — Consecutive future days covered by approved content with channel, date and owner. Source: Content calendar | E19: BM-K01 | F19: Weekly check; monthly minimum | G19: 6 | K19: =IF(COUNT(H19:J19)=0,"",AVERAGE(H19:J19)) | L19: =IF(K19="","",G19*K19)
A20: 7 | B20: KPI | C20: On-time publication rate | D20: ≥95% — Scheduled posts published at the agreed time ÷ posts due (approved cancellations shown separately). Source: Content calendar; channel logs | E20: BM-K02 | F20: Monthly | G20: 6 | K20: =IF(COUNT(H20:J20)=0,"",AVERAGE(H20:J20)) | L20: =IF(K20="","",G20*K20)
A21: 8 | B21: KPI | C21: Social-to-app click-through rate | D21: [TBC] — October baseline + 20% — Clicks on tracked app links from organic social posts ÷ reach of those posts (per 1,000). Source: Link shortener or UTM report; platform insights (no app analytics needed) | E21: BM-K11 | F21: Monthly | G21: 7 | K21: =IF(COUNT(H21:J21)=0,"",AVERAGE(H21:J21)) | L21: =IF(K21="","",G21*K21)
A22: 9 | B22: KPI | C22: Tracked-link coverage rate | D22: 100% — Posts and placements promoting an in-app item that carry a working tracked link ÷ such posts and placements. Source: Content calendar; link report | E22: BM-K13 | F22: Monthly | G22: 3 | K22: =IF(COUNT(H22:J22)=0,"",AVERAGE(H22:J22)) | L22: =IF(K22="","",G22*K22)
A23: 10 | B23: KPI | C23: Social enquiry response rate | D23: ≥90% — Social enquiries answered or routed to the owning team within 1 business day ÷ enquiries received. Source: Social inbox | E23: BM-K10 | F23: Monthly | G23: 3 | K23: =IF(COUNT(H23:J23)=0,"",AVERAGE(H23:J23)) | L23: =IF(K23="","",G23*K23)
A24: Accountability — 15%
A25: 11 | B25: Accountability | C25: On-time commitment delivery rate | D25: ≥80% of your agreed monthly commitments in the company register delivered by the original date | E25: CO-KR6.1 | F25: Monthly | G25: 10 | K25: =IF(COUNT(H25:J25)=0,"",AVERAGE(H25:J25)) | L25: =IF(K25="","",G25*K25)
A26: 12 | B26: Accountability | C26: Monthly update on time | D26: Target–Actual–Variance–Action update to your reviewer by the 2nd business day of each month | E26: PC-K06 | F26: Monthly | G26: 5 | K26: =IF(COUNT(H26:J26)=0,"",AVERAGE(H26:J26)) | L26: =IF(K26="","",G26*K26)
J28: Total weight | L28: =SUM(G12:G26) -> 100
J29: Score to date | L29: =IFERROR(SUM(L12:L26)/SUMPRODUCT((K12:K26<>"")*G12:G26),"")
J30: Rating | L30: =IF(L29="","",IF(L29>=0.9,"Exceeds",IF(L29>=0.75,"Meets",IF(L29>=0.5,"Partly meets","Below"))))
A32: Agreement — to be signed by 25 September 2026 at the latest
C33: Employee: Aaron Agama Signature / date: ______________ | D33: Reviewer: Chinyere Elechi Signature / date: ______________

Sheet 00014 Abubakar Mohammed
A1: Q4 2026 scorecard — Abubakar Mohammed
A3: Staff ID | B3: 00014
A4: Designation | B4: Head Strategy, Partnerships & Growth
A5: Team | B5: Partnership & Growth
A6: OKR function | B6: Partnership & Growth
A7: Reviewer | B7: Ifeoma Mbonu
A8: Scope | B8: Function leadership; Lagos and national accounts; interim Kano cover
A9: Period | B9: 1 Oct – 31 Dec 2026
A11: # | B11: Section | C11: Goal / KPI | D11: Target and how it is measured | E11: Linked KR / KPI | F11: Due / frequency | G11: Weight | H11: Oct | I11: Nov | J11: Dec | K11: Score (0–1) | L11: Weighted
A12: Results — 60%
A13: 1 | B13: Result | C13: Event portfolio (function) | D13: 200 ticketed events in Q4 under signed commission terms, 25 of them December exclusives (your direct Lagos and Kano share: 110 events, 17 exclusives) | E13: PG-KR1.1 | F13: 31 Dec | G13: 12 | K13: =IF(J13<>"",J13,IF(I13<>"",I13,IF(H13<>"",H13,""))) | L13: =IF(K13="","",G13*K13)
A14: 2 | B14: Result | C14: Lagos stays for December | D14: 150 Lagos hotels and shortlets with signed terms (December inventory, 2-hour confirmation, fee, exclusive benefit) by 20 Nov | E14: PG-KR1.2 | F14: 20 Nov | G14: 12 | K14: =IF(J14<>"",J14,IF(I14<>"",I14,IF(H14<>"",H14,""))) | L14: =IF(K14="","",G14*K14)
A15: 3 | B15: Result | C15: Partners for the Q1 launch (function) | D15: 150 restaurants and 100 hotels/shortlets across Lagos and Abuja signed by 31 Dec (your Lagos share: 90 restaurants, 50 stays) | E15: PG-KR1.3 | F15: 31 Dec | G15: 8 | K15: =IF(J15<>"",J15,IF(I15<>"",I15,IF(H15<>"",H15,""))) | L15: =IF(K15="","",G15*K15)
A16: 4 | B16: Result | C16: December advertising revenue | D16: ₦8m [TBC] advertising and brand-partnership revenue earned in December | E16: PG-KR2.1 | F16: 31 Dec | G16: 12 | K16: =IF(J16<>"",J16,IF(I16<>"",I16,IF(H16<>"",H16,""))) | L16: =IF(K16="","",G16*K16)
A17: 5 | B17: Result | C17: Alpha Beta/LASG agreement | D17: Agreement signed by 15 Oct, covering bill types, platform fee, settlement and refund responsibilities | E17: PG-KR2.2 | F17: 15 Oct | G17: 8 | K17: =IF(J17<>"",J17,IF(I17<>"",I17,IF(H17<>"",H17,""))) | L17: =IF(K17="","",G17*K17)
A18: 6 | B18: Result | C18: Ticketing commission (function) | D18: ₦5m [TBC] ticketing commission earned in Q4 from signed events (your direct Lagos and Kano accounts: ₦2.75m) | E18: PG-KR2.3 | F18: 31 Dec | G18: 4 | K18: =IF(J18<>"",J18,IF(I18<>"",I18,IF(H18<>"",H18,""))) | L18: =IF(K18="","",G18*K18)
A19: 7 | B19: Result | C19: Distribution placements (function) | D19: 30 [TBC] live distribution placements secured in Q4, each handed to Marketing with audience and tracked link (your direct share: 12) | E19: PG-KR3.1 | F19: 31 Dec | G19: 4 | K19: =IF(J19<>"",J19,IF(I19<>"",I19,IF(H19<>"",H19,""))) | L19: =IF(K19="","",G19*K19)
A20: KPIs — 25%
A21: 8 | B21: KPI | C21: Qualified pipeline coverage ratio | D21: ≥3.0× — Platform revenue expected in Q4 from qualified open opportunities ÷ remaining Q4 revenue target (excludes ticket value and GMV). Source: Pipeline register | E21: PG-K01 | F21: Monthly | G21: 7 | K21: =IF(COUNT(H21:J21)=0,"",AVERAGE(H21:J21)) | L21: =IF(K21="","",G21*K21)
A22: 9 | B22: KPI | C22: On-time invoice collection rate | D22: ≥95% — Cash received by the invoice due date ÷ invoiced amounts due. Source: Finance records | E22: PG-K05 | F22: Monthly | G22: 6 | K22: =IF(COUNT(H22:J22)=0,"",AVERAGE(H22:J22)) | L22: =IF(K22="","",G22*K22)
A23: 10 | B23: KPI | C23: Commercial approval-limit compliance rate | D23: 100% — Deals agreed within approved pricing and discount authority ÷ deals agreed. Source: Deal approvals log | E23: PG-K07 | F23: Monthly | G23: 6 | K23: =IF(COUNT(H23:J23)=0,"",AVERAGE(H23:J23)) | L23: =IF(K23="","",G23*K23)
A24: 11 | B24: KPI | C24: Partner booking confirmation rate | D24: ≥90% — Stay and restaurant requests confirmed or declined by the partner within 2 hours ÷ requests received. Source: Booking back office | E24: PG-K04 | F24: Weekly in December; monthly | G24: 6 | K24: =IF(COUNT(H24:J24)=0,"",AVERAGE(H24:J24)) | L24: =IF(K24="","",G24*K24)
A25: Accountability — 15%
A26: 12 | B26: Accountability | C26: On-time commitment delivery rate | D26: ≥80% of your CEO-approved monthly commitments in the company register delivered by the original date | E26: CO-KR6.1 | F26: Monthly | G26: 8 | K26: =IF(COUNT(H26:J26)=0,"",AVERAGE(H26:J26)) | L26: =IF(K26="","",G26*K26)
A27: 13 | B27: Accountability | C27: Monthly function report on time | D27: Target–Actual–Variance–Action report submitted by the 3rd business day of each month | E27: PC-K06 | F27: Monthly | G27: 3 | K27: =IF(COUNT(H27:J27)=0,"",AVERAGE(H27:J27)) | L27: =IF(K27="","",G27*K27)
A28: 14 | B28: Accountability | C28: Team scorecards and reviews | D28: Every direct report has a signed scorecard by 25 Sep; October and November reviews completed by 15 Dec | E28: PC-KR1.1; PC-KR1.2 | F28: 25 Sep; 15 Dec | G28: 4 | K28: =IF(COUNT(H28:J28)=0,"",AVERAGE(H28:J28)) | L28: =IF(K28="","",G28*K28)
J30: Total weight | L30: =SUM(G12:G28) -> 100
J31: Score to date | L31: =IFERROR(SUM(L12:L28)/SUMPRODUCT((K12:K28<>"")*G12:G28),"")
J32: Rating | L32: =IF(L31="","",IF(L31>=0.9,"Exceeds",IF(L31>=0.75,"Meets",IF(L31>=0.5,"Partly meets","Below"))))
A34: Agreement — to be signed by 25 September 2026 at the latest
C35: Employee: Abubakar Mohammed Signature / date: ______________ | D35: Reviewer: Ifeoma Mbonu Signature / date: ______________

Sheet 00016 Bode Oluwasanmi
A1: Q4 2026 scorecard — Bode Oluwasanmi
A3: Staff ID | B3: 00016
A4: Designation | B4: Chief Technology Officer
A5: Team | B5: Technology
A6: OKR function | B6: Technology
A7: Reviewer | B7: Ifeoma Mbonu
A8: Scope | B8: All three apps; MTNN and other delivery vendors
A9: Period | B9: 1 Oct – 31 Dec 2026
A11: # | B11: Section | C11: Goal / KPI | D11: Target and how it is measured | E11: Linked KR / KPI | F11: Due / frequency | G11: Weight | H11: Oct | I11: Nov | J11: Dec | K11: Score (0–1) | L11: Weighted
A12: Results — 60%
A13: 1 | B13: Result | C13: Analytics live | D13: Product analytics tool contracted by 15 Oct; seven journeys instrumented by 15 Nov; November figures reconcile to provider records within 2% | E13: TECH-KR1.3 | F13: 15 Oct; 15 Nov; 5 Dec | G13: 10 | K13: =IF(J13<>"",J13,IF(I13<>"",I13,IF(H13<>"",H13,""))) | L13: =IF(K13="","",G13*K13)
A14: 2 | B14: Result | C14: Payment success | D14: Bill-payment and LASG-payment success ≥95% in December, no day below 90% | E14: TECH-KR1.1 | F14: 31 Dec | G14: 10 | K14: =IF(J14<>"",J14,IF(I14<>"",I14,IF(H14<>"",H14,""))) | L14: =IF(K14="","",G14*K14)
A15: 3 | B15: Result | C15: Ticket purchase success | D15: ≥97% of valid ticket purchases in December produce a valid ticket; zero duplicate charges and zero oversold events | E15: TECH-KR1.2 | F15: 31 Dec | G15: 10 | K15: =IF(J15<>"",J15,IF(I15<>"",I15,IF(H15<>"",H15,""))) | L15: =IF(K15="","",G15*K15)
A16: 4 | B16: Result | C16: LASG payments live | D16: LASG payments live in MyLagosApp by 15 Nov, with receipts, refunds and settlement records | E16: TECH-KR2.1 | F16: 15 Nov | G16: 8 | K16: =IF(J16<>"",J16,IF(I16<>"",I16,IF(H16<>"",H16,""))) | L16: =IF(K16="","",G16*K16)
A17: 5 | B17: Result | C17: Assisted stay booking live | D17: Hotel and shortlet request, partner confirmation, payment and status updates live in MyLagosApp by 30 Nov | E17: TECH-KR2.2 | F17: 30 Nov | G17: 8 | K17: =IF(J17<>"",J17,IF(I17<>"",I17,IF(H17<>"",H17,""))) | L17: =IF(K17="","",G17*K17)
A18: 6 | B18: Result | C18: Notification controls | D18: Frequency caps, quiet hours and preference centre live in both apps by 31 Oct | E18: TECH-KR2.4 | F18: 31 Oct | G18: 6 | K18: =IF(J18<>"",J18,IF(I18<>"",I18,IF(H18<>"",H18,""))) | L18: =IF(K18="","",G18*K18)
A19: 7 | B19: Result | C19: MTNN delivery reliability | D19: ≥80% of MTNN roadmap milestones due Oct–Dec accepted by their committed date | E19: TECH-KR2.3 | F19: 31 Dec | G19: 8 | K19: =IF(J19<>"",J19,IF(I19<>"",I19,IF(H19<>"",H19,""))) | L19: =IF(K19="","",G19*K19)
A20: KPIs — 25%
A21: 8 | B21: KPI | C21: Payment and ticketing service availability rate | D21: ≥99.5% — Minutes the monitored payment and ticketing services are usable ÷ total minutes in the month (planned outages count as downtime). Source: Uptime monitor; MTNN incident log | E21: TECH-K01 | F21: Monthly | G21: 7 | K21: =IF(COUNT(H21:J21)=0,"",AVERAGE(H21:J21)) | L21: =IF(K21="","",G21*K21)
A22: 9 | B22: KPI | C22: Priority-1 incident recovery rate | D22: ≥90% — Customer-affecting P1 incidents restored within 4 hours ÷ P1 incidents in the month. Source: Incident log | E22: TECH-K02 | F22: Monthly | G22: 6 | K22: =IF(COUNT(H22:J22)=0,"",AVERAGE(H22:J22)) | L22: =IF(K22="","",G22*K22)
A23: 10 | B23: KPI | C23: Next-day transaction matching rate | D23: 100% — Settled transactions matched to order, provider and settlement references by the next business day ÷ settled transactions. Source: Reconciliation report | E23: TECH-K03 | F23: Daily; reported monthly | G23: 6 | K23: =IF(COUNT(H23:J23)=0,"",AVERAGE(H23:J23)) | L23: =IF(K23="","",G23*K23)
A24: 11 | B24: KPI | C24: Overdue production-access removals | D24: 0 — Number of departed or unauthorised users still holding production access after the removal cut-off. Source: Access register; P&C exit list | E24: TECH-K05 | F24: Monthly maximum | G24: 6 | K24: =IF(COUNT(H24:J24)=0,"",AVERAGE(H24:J24)) | L24: =IF(K24="","",G24*K24)
A25: Accountability — 15%
A26: 12 | B26: Accountability | C26: On-time commitment delivery rate | D26: ≥80% of your agreed monthly commitments in the company register delivered by the original date | E26: CO-KR6.1 | F26: Monthly | G26: 10 | K26: =IF(COUNT(H26:J26)=0,"",AVERAGE(H26:J26)) | L26: =IF(K26="","",G26*K26)
A27: 13 | B27: Accountability | C27: Monthly update on time | D27: Target–Actual–Variance–Action update to your reviewer by the 2nd business day of each month | E27: PC-K06 | F27: Monthly | G27: 5 | K27: =IF(COUNT(H27:J27)=0,"",AVERAGE(H27:J27)) | L27: =IF(K27="","",G27*K27)
J29: Total weight | L29: =SUM(G12:G27) -> 100
J30: Score to date | L30: =IFERROR(SUM(L12:L27)/SUMPRODUCT((K12:K27<>"")*G12:G27),"")
J31: Rating | L31: =IF(L30="","",IF(L30>=0.9,"Exceeds",IF(L30>=0.75,"Meets",IF(L30>=0.5,"Partly meets","Below"))))
A33: Agreement — to be signed by 25 September 2026 at the latest
C34: Employee: Bode Oluwasanmi Signature / date: ______________ | D34: Reviewer: Ifeoma Mbonu Signature / date: ______________

Sheet 00017 Gideon Ekom
A1: Q4 2026 scorecard — Gideon Ekom
A3: Staff ID | B3: 00017
A4: Designation | B4: Marketing & Growth Officer - Enugu
A5: Team | B5: Partnership & Growth
A6: OKR function | B6: Partnership & Growth
A7: Reviewer | B7: Abubakar Mohammed
A8: Scope | B8: South East — Enugu
A9: Period | B9: 1 Oct – 31 Dec 2026
A11: # | B11: Section | C11: Goal / KPI | D11: Target and how it is measured | E11: Linked KR / KPI | F11: Due / frequency | G11: Weight | H11: Oct | I11: Nov | J11: Dec | K11: Score (0–1) | L11: Weighted
A12: Results — 60%
A13: 1 | B13: Result | C13: Enugu ticketed events | D13: 10 ticketed Enugu events live in Q4 under signed commission terms, 1 of them a December event on app-exclusive terms | E13: PG-KR1.1 | F13: 31 Dec | G13: 15 | K13: =IF(J13<>"",J13,IF(I13<>"",I13,IF(H13<>"",H13,""))) | L13: =IF(K13="","",G13*K13)
A14: 2 | B14: Result | C14: Ticketing commission — Enugu accounts | D14: ₦250,000 [TBC] ticketing commission earned in Q4 from events you signed, at the contracted rate net of refunds (account owner on the pipeline record) | E14: PG-KR2.3 | F14: 31 Dec | G14: 15 | K14: =IF(J14<>"",J14,IF(I14<>"",I14,IF(H14<>"",H14,""))) | L14: =IF(K14="","",G14*K14)
A15: 3 | B15: Result | C15: Distribution placements — Enugu | D15: 3 live placements secured in Enugu (hotel guest messages, event ticket emails, association channels), each with an agreed audience and a tracked link, handed to Marketing within 2 business days | E15: PG-KR3.1 | F15: 31 Dec | G15: 15 | K15: =IF(J15<>"",J15,IF(I15<>"",I15,IF(H15<>"",H15,""))) | L15: =IF(K15="","",G15*K15)
A16: 4 | B16: Result | C16: Enugu business submissions | D16: 500 owner-confirmed Enugu business submissions accepted by Operations in Q4 | E16: OP-KR2.2 | F16: 31 Dec | G16: 15 | K16: =IF(J16<>"",J16,IF(I16<>"",I16,IF(H16<>"",H16,""))) | L16: =IF(K16="","",G16*K16)
A17: KPIs — 25%
A18: 5 | B18: KPI | C18: On-time partner launch rate | D18: ≥90% — Signed partners and events live on the agreed date ÷ launches due (overdue launches stay in). Source: Pipeline register; publishing queue | E18: PG-K02 | F18: Monthly | G18: 10 | K18: =IF(COUNT(H18:J18)=0,"",AVERAGE(H18:J18)) | L18: =IF(K18="","",G18*K18)
A19: 6 | B19: KPI | C19: Signed-deal handover rate | D19: ≥95% — Signed deals accepted by the delivering team within 2 business days of signature ÷ deals signed. Source: Handover log | E19: PG-K03 | F19: Monthly | G19: 8 | K19: =IF(COUNT(H19:J19)=0,"",AVERAGE(H19:J19)) | L19: =IF(K19="","",G19*K19)
A20: 7 | B20: KPI | C20: Overdue sales follow-ups | D20: 0 — Qualified opportunities whose agreed next action is more than 5 business days overdue. Source: Pipeline register | E20: PG-K08 | F20: Weekly; monthly maximum | G20: 7 | K20: =IF(COUNT(H20:J20)=0,"",AVERAGE(H20:J20)) | L20: =IF(K20="","",G20*K20)
A21: Accountability — 15%
A22: 8 | B22: Accountability | C22: On-time commitment delivery rate | D22: ≥80% of your agreed monthly commitments in the company register delivered by the original date | E22: CO-KR6.1 | F22: Monthly | G22: 10 | K22: =IF(COUNT(H22:J22)=0,"",AVERAGE(H22:J22)) | L22: =IF(K22="","",G22*K22)
A23: 9 | B23: Accountability | C23: Monthly update on time | D23: Target–Actual–Variance–Action update to your reviewer by the 2nd business day of each month | E23: PC-K06 | F23: Monthly | G23: 5 | K23: =IF(COUNT(H23:J23)=0,"",AVERAGE(H23:J23)) | L23: =IF(K23="","",G23*K23)
J25: Total weight | L25: =SUM(G12:G23) -> 100
J26: Score to date | L26: =IFERROR(SUM(L12:L23)/SUMPRODUCT((K12:K23<>"")*G12:G23),"")
J27: Rating | L27: =IF(L26="","",IF(L26>=0.9,"Exceeds",IF(L26>=0.75,"Meets",IF(L26>=0.5,"Partly meets","Below"))))
A29: Agreement — to be signed by 25 September 2026 at the latest
